Workbook
Name current_price: [1]Summary!$C$8
Name Scenario: Segment!$B$3

Sheet BCLO
E2: Model Summary
E3: Bausch + Lomb (BCLO) | F3: 45064 | G3: =EOMONTH(F3,3) -> 45169 | H3: =EOMONTH(G3,3) -> 45260 | I3: =EOMONTH(H3,3) -> 45351 | J3: =EOMONTH(I3,3) -> 45443 | K3: =J3 -> 45443 | L3: =EOMONTH(K3,3) -> 45535 | M3: =EOMONTH(L3,3) -> 45626 | N3: =EOMONTH(M3,3) -> 45716 | O3: =EOMONTH(N3,3) -> 45808 | P3: =O3 -> 45808 | Q3: =EOMONTH(P3,3) -> 45900 | R3: =EOMONTH(Q3,3) -> 45991 | S3: =EOMONTH(R3,3) -> 46081 | T3: =EOMONTH(S3,3) -> 46173 | U3: =T3 -> 46173 | V3: =EOMONTH(U3,3) -> 46265 | W3: =EOMONTH(V3,3) -> 46356 | X3: =EOMONTH(W3,3) -> 46446 | Y3: =EOMONTH(X3,3) -> 46538 | Z3: =Y3 -> 46538 | AA3: =EOMONTH(Z3,3) -> 46630 | AB3: =EOMONTH(AA3,3) -> 46721 | AC3: =EOMONTH(AB3,3) -> 46812 | AD3: =EOMONTH(AC3,3) -> 46904 | AE3: =AD3 -> 46904 | AF3: =EOMONTH(AE3,3) -> 46996 | AG3: =EOMONTH(AF3,3) -> 47087 | AH3: =EOMONTH(AG3,3) -> 47177 | AI3: =EOMONTH(AH3,3) -> 47269 | AJ3: =AI3 -> 47269 | AK3: =EOMONTH(AJ3,3) -> 47361 | AL3: =EOMONTH(AK3,3) -> 47452 | AM3: =EOMONTH(AL3,3) -> 47542 | AN3: =EOMONTH(AM3,3) -> 47634 | AO3: =AN3 -> 47634 | AP3: 47999 | AQ3: 48335 | AR3: 48335
E4: $ Million | F4: =YEAR(F3)-1&"A" -> 2022A | G4: ="Q1 "& YEAR(G3) -> Q1 2023 | H4: ="Q2 "& YEAR(H3) -> Q2 2023 | I4: ="Q3 "& YEAR(I3) -> Q3 2024 | J4: ="Q4 "& YEAR(J3)-1 -> Q4 2023 | K4: =YEAR(K3)-1&"A" -> 2023A | L4: ="Q1 "& YEAR(L3) -> Q1 2024 | M4: ="Q2 "& YEAR(M3) -> Q2 2024 | N4: ="Q3 "& YEAR(N3) -> Q3 2025 | O4: ="Q4 "& YEAR(O3)-1 -> Q4 2024 | P4: =YEAR(P3)-1&"A" -> 2024A | Q4: ="Q1 "& YEAR(Q3) -> Q1 2025 | R4: ="Q2 "& YEAR(R3) -> Q2 2025 | S4: ="Q3 "& YEAR(S3) -> Q3 2026 | T4: ="Q4 "& YEAR(T3)-1 -> Q4 2025 | U4: =YEAR(U3)-1&"A" -> 2025A | V4: ="Q1 "& YEAR(V3) -> Q1 2026 | W4: ="Q2 "& YEAR(W3) -> Q2 2026 | X4: ="Q3 "& YEAR(X3) -> Q3 2027 | Y4: ="Q4 "& YEAR(Y3)-1 -> Q4 2026 | Z4: =YEAR(Z3)-1&"A" -> 2026A | AA4: ="Q1 "& YEAR(AA3) -> Q1 2027 | AB4: ="Q2 "& YEAR(AB3) -> Q2 2027 | AC4: ="Q3 "& YEAR(AC3) -> Q3 2028 | AD4: ="Q4 "& YEAR(AD3)-1 -> Q4 2027 | AE4: =YEAR(AE3)-1&"A" -> 2027A | AF4: ="Q1 "& YEAR(AF3) -> Q1 2028 | AG4: ="Q2 "& YEAR(AG3) -> Q2 2028 | AH4: ="Q3 "& YEAR(AH3) -> Q3 2029 | AI4: ="Q4 "& YEAR(AI3)-1 -> Q4 2028 | AJ4: =YEAR(AJ3)-1&"E" -> 2028E | AK4: ="Q1 "& YEAR(AK3) -> Q1 2029 | AL4: ="Q2 "& YEAR(AL3) -> Q2 2029 | AM4: ="Q3 "& YEAR(AM3) -> Q3 2030 | AN4: ="Q4 "& YEAR(AN3)-1 -> Q4 2029 | AO4: =YEAR(AO3)-1&"E" -> 2029E | AP4: =YEAR(AP3)-1&"E" -> 2030E | AQ4: =YEAR(AQ3)-1&"E" -> 2031E | AR4: =YEAR(AR3)-1&"E" -> 2031E
A5: Bausch + Lomb | E5: Key Perfomormance Indicators
A6: Author | D6: Owen Purnomo | E6: Vision Care Revenue | F6: =Segment!F8 -> 2369 | G6: =Segment!G8 -> 0 | H6: =Segment!H8 -> 0 | I6: =Segment!I8 -> 0 | J6: =Segment!J8 -> 0 | K6: =Segment!K8 -> 2543 | L6: =Segment!L8 -> 0 | M6: =Segment!M8 -> 0 | ... AR6: =Segment!AR8 -> 3965.8181
A7: Ticker | D7: BCLO | E7: Comp YoY | F7: - | K7: =Segment!K9 -> 0.073448713 | L7: =Segment!L9 -> #DIV/0! | M7: =Segment!M9 -> #DIV/0! | N7: =Segment!N9 -> #DIV/0! | O7: =Segment!O9 -> #DIV/0! | P7: =Segment!P9 -> 0.077074322 | Q7: =Segment!Q9 -> #DIV/0! | R7: =Segment!R9 -> #DIV/0! | ... AR7: =Segment!AR9 -> 0.03
A8: Current Price | D8: 16.82 | E8: Pharmaceutial Revenue | F8: =Segment!F13 -> 681 | G8: =Segment!G13 -> 0 | H8: =Segment!H13 -> 0 | I8: =Segment!I13 -> 0 | J8: =Segment!J13 -> 0 | K8: =Segment!K13 -> 836 | L8: =Segment!L13 -> 0 | M8: =Segment!M13 -> 0 | ... AR8: =Segment!AR13 -> 1624.6934
E9: Comp YoY | F9: =Segment!F9 -> - | G9: =Segment!G9 -> 0 | H9: =Segment!H9 -> 0 | I9: =Segment!I9 -> 0 | J9: =Segment!J9 -> 0 | K9: =Segment!K9 -> 0.073448713 | L9: =Segment!L9 -> #DIV/0! | M9: =Segment!M9 -> #DIV/0! | ... AR9: =Segment!AR9 -> 0.03
E10: Surgical Revenue | F10: =Segment!F18 -> 718 | G10: =Segment!G18 -> 0 | H10: =Segment!H18 -> 0 | I10: =Segment!I18 -> 0 | J10: =Segment!J18 -> 0 | K10: =Segment!K18 -> 767 | L10: =Segment!L18 -> 0 | M10: =Segment!M18 -> 0 | ... AR10: =Segment!AR18 -> 1288.6786
E11: Comp YoY | F11: =Segment!F19 -> - | G11: =Segment!G19 -> 0 | H11: =Segment!H19 -> 0 | I11: =Segment!I19 -> 0 | J11: =Segment!J19 -> 0 | K11: =Segment!K19 -> 0.068245125 | L11: =Segment!L19 -> #DIV/0! | M11: =Segment!M19 -> #DIV/0! | ... AR11: =Segment!AR19 -> 0.04
E12: Income Statement
E13: Revenues | F13: =Segment!F6 -> 3768 | G13: =Segment!G6 -> 0 | H13: =Segment!H6 -> 0 | I13: =Segment!I6 -> 0 | J13: =Segment!J6 -> 0 | K13: =Segment!K6 -> 4146 | L13: =Segment!L6 -> 0 | M13: =Segment!M6 -> 0 | ... AR13: =Segment!AR6 -> 6879.1902
E14: YoY Growth | F14: - | K14: =K13/F13-1 -> 0.10031847 | L14: =L13/G13-1 -> #DIV/0! | M14: =M13/H13-1 -> #DIV/0! | N14: =N13/I13-1 -> #DIV/0! | O14: =O13/J13-1 -> #DIV/0! | P14: =P13/K13-1 -> 0.15557164 | Q14: =Q13/L13-1 -> #DIV/0! | R14: =R13/M13-1 -> #DIV/0! | ... AO14: =AO13/AJ13-1 -> 0.049348819 | AP14: =AP13/AO13-1 -> 0.029388899 | AQ14: =AQ13/AP13-1 -> 0.02942977 | AR14: =AR13/AQ13-1 -> 0.029470654
E15: Cost of Sales | F15: =Segment!F26+8 -> 1519 | G15: =Segment!G26 -> 0 | H15: =Segment!H26 -> 0 | I15: =Segment!I26 -> 0 | J15: =Segment!J26 -> 0 | K15: =Segment!K26+2 -> 1642 | L15: =Segment!L26 -> 0 | M15: =Segment!M26 -> 0 | N15: =Segment!N26 -> 0 | O15: =Segment!O26 -> 0 | P15: =Segment!P26+2 -> 1870 | Q15: =Segment!Q26 -> 0 | R15: =Segment!R26 -> 0 | S15: =Segment!S26 -> 0 | T15: =Segment!T26 -> 0 | U15: =Segment!U26+5 -> 2050 | V15: =Segment!V26 -> 0 | W15: =Segment!W26 -> 0 | X15: =Segment!X26 -> 0 | Y15: =Segment!Y26 -> 0 | Z15: =Segment!Z26 -> 2183.2187 | AA15: =Segment!AA26 -> 0 | AB15: =Segment!AB26 -> 0 | AC15: =Segment!AC26 -> 0 | ... AR15: =Segment!AR26 -> 2751.6761
E16: Gross Profit | F16: =F13-F15 -> 2249 | G16: =G13-G15 -> 0 | H16: =H13-H15 -> 0 | I16: =I13-I15 -> 0 | J16: =J13-J15 -> 0 | K16: =K13-K15 -> 2504 | L16: =L13-L15 -> 0 | M16: =M13-M15 -> 0 | ... AR16: =AR13-AR15 -> 4127.5141
E17: Gross Margin % | F17: =F16/F13 -> 0.59686837 | G17: =G16/G13 -> #DIV/0! | H17: =H16/H13 -> #DIV/0! | I17: =I16/I13 -> #DIV/0! | J17: =J16/J13 -> #DIV/0! | K17: =K16/K13 -> 0.60395562 | L17: =L16/L13 -> #DIV/0! | M17: =M16/M13 -> #DIV/0! | ... AR17: =AR16/AR13 -> 0.6
E18: SG&A | F18: 1478 | K18: 1736 | P18: 2082 | U18: 2234 | Z18: =Z13*Z19 -> 2297.1357 | AA18: =AA13*AA19 -> #DIV/0! | AB18: =AB13*AB19 -> #DIV/0! | AC18: =AC13*AC19 -> #DIV/0! | AD18: =AD13*AD19 -> #DIV/0! | AE18: =AE13*AE19 -> 2451.2901 | AF18: =AF13*AF19 -> #DIV/0! | AG18: =AG13*AG19 -> #DIV/0! | ... AR18: =AR13*AR19 -> 2953.2455
E19: As % of Sales | F19: =F18/F13 -> 0.39225053 | G19: =G18/G13 -> #DIV/0! | H19: =H18/H13 -> #DIV/0! | I19: =I18/I13 -> #DIV/0! | J19: =J18/J13 -> #DIV/0! | K19: =K18/K13 -> 0.41871684 | L19: =L18/L13 -> #DIV/0! | M19: =M18/M13 -> #DIV/0! | ... Y19: =Y18/Y13 -> #DIV/0! | Z19: =AVERAGE(F19,K19,P19,U19) -> 0.42087138 | AA19: =AVERAGE(G19,L19,Q19,V19) -> #DIV/0! | AB19: =AVERAGE(H19,M19,R19,W19) -> #DIV/0! | AC19: =AVERAGE(I19,N19,S19,X19) -> #DIV/0! | AD19: =AVERAGE(J19,O19,T19,Y19) -> #DIV/0! | AE19: =AVERAGE(K19,P19,U19,Z19) -> 0.42802659 | AF19: =AVERAGE(L19,Q19,V19,AA19) -> #DIV/0! | AG19: =AVERAGE(M19,R19,W19,AB19) -> #DIV/0! | ... AO19: =AVERAGE(U19,Z19,AE19,AJ19) -> 0.42930134 | AP19: =AVERAGE(U19,Z19,AE19,AJ19,AO19) -> 0.42930134 | AQ19: =AP19 -> 0.42930134 | AR19: =AQ19 -> 0.42930134
E20: R&D Expense | F20: 307 | K20: 324 | P20: 343 | U20: 371 | Z20: =Z13*Z21 -> 414.73869 | AE20: =AE13*AE21 -> 435.17233 | AF20: =AF13*AF21 -> 0 | AG20: =AG13*AG21 -> 0 | AH20: =AH13*AH21 -> 0 | AI20: =AI13*AI21 -> 0 | AJ20: =AJ13*AJ21 -> 456.63013 | AK20: =AK13*AK21 -> 0 | AL20: =AL13*AL21 -> 0 | ... AR20: =AR13*AR21 -> 522.72662
E21: As % of Sales | F21: =F20/F13 -> 0.081475584 | G21: =G20/G13 -> #DIV/0! | H21: =H20/H13 -> #DIV/0! | I21: =I20/I13 -> #DIV/0! | J21: =J20/J13 -> #DIV/0! | K21: =K20/K13 -> 0.078147612 | L21: =L20/L13 -> #DIV/0! | M21: =M20/M13 -> #DIV/0! | ... Y21: =Y20/Y13 -> #DIV/0! | Z21: =AVERAGE(F21,K21,P21,U21) -> 0.075986651 | AA21: =AVERAGE(G21,L21,Q21,V21) -> #DIV/0! | AB21: =AVERAGE(H21,M21,R21,W21) -> #DIV/0! | AC21: =AVERAGE(I21,N21,S21,X21) -> #DIV/0! | AD21: =AVERAGE(J21,O21,T21,Y21) -> #DIV/0! | AE21: =$Z$21 -> 0.075986651 | AF21: =$Z$21 -> 0.075986651 | AG21: =$Z$21 -> 0.075986651 | AH21: =$Z$21 -> 0.075986651 | AI21: =$Z$21 -> 0.075986651 | AJ21: =$Z$21 -> 0.075986651 | AK21: =$Z$21 -> 0.075986651 | AL21: =$Z$21 -> 0.075986651 | ... AR21: =$Z$21 -> 0.075986651
E22: Other Expenses | F22: 13 | K22: 74 | P22: 44 | U22: 75 | Z22: =AVERAGE(F22:U22) -> 51.5 | AA22: =AVERAGE(G22:V22) -> 64.333333 | AB22: =AVERAGE(H22:W22) -> 64.333333 | AC22: =AVERAGE(I22:X22) -> 64.333333 | AD22: =AVERAGE(J22:Y22) -> 64.333333 | AE22: =AVERAGE(K22:Z22) -> 61.125 | AF22: =AVERAGE(L22:AA22) -> 58.708333 | AG22: =AVERAGE(M22:AB22) -> 59.833333 | ... AO22: =AVERAGE(U22:AJ22) -> 62.193514 | AP22: =AO22 -> 62.193514 | AQ22: =AP22 -> 62.193514 | AR22: =AQ22 -> 62.193514
E23: EBITDA | F23: =F16-F18-F20-F22 -> 451 | G23: =G16-G18-G20-G22 -> 0 | H23: =H16-H18-H20-H22 -> 0 | I23: =I16-I18-I20-I22 -> 0 | J23: =J16-J18-J20-J22 -> 0 | K23: =K16-K18-K20-K22 -> 370 | L23: =L16-L18-L20-L22 -> 0 | M23: =M16-M18-M20-M22 -> 0 | ... AR23: =AR16-AR18-AR20-AR22 -> 589.34844
E24: Margin % | F24: =F23/F13 -> 0.11969214 | G24: =G23/G13 -> #DIV/0! | H24: =H23/H13 -> #DIV/0! | I24: =I23/I13 -> #DIV/0! | J24: =J23/J13 -> #DIV/0! | K24: =K23/K13 -> 0.089242644 | L24: =L23/L13 -> #DIV/0! | M24: =M23/M13 -> #DIV/0! | ... AR24: =AR23/AR13 -> 0.085671194
E25: Asset Impairments | F25: 15 | K25: 54 | P25: 29 | U25: 20
E26: Goodwill Impairments | F26: 824 | K26: 493 | P26: 0 | U26: 0
E27: Restructuring | F27: 63 | K27: 62 | P27: 32 | U27: 30
E28: Other Adjustments (Non-Recurring) | F28: 0 | K28: 0 | P28: 207 | U28: 60
E29: Total Add-backs | F29: =SUM(F25:F28) -> 902 | G29: =SUM(G25:G28) -> 0 | H29: =SUM(H25:H28) -> 0 | I29: =SUM(I25:I28) -> 0 | J29: =SUM(J25:J28) -> 0 | K29: =SUM(K25:K28) -> 609 | L29: =SUM(L25:L28) -> 0 | M29: =SUM(M25:M28) -> 0 | ... U29: =SUM(U25:U28) -> 110
E30: Adjusted EBITDA | F30: =F23+F29 -> 1353 | G30: =G23+G29 -> 0 | H30: =H23+H29 -> 0 | I30: =I23+I29 -> 0 | J30: =J23+J29 -> 0 | K30: =K23+K29 -> 979 | L30: =L23+L29 -> 0 | M30: =M23+M29 -> 0 | ... AR30: =AR23+AR29 -> 589.34844
E31: Margin % | F31: =F30/F13 -> 0.35907643 | G31: =G30/G13 -> #DIV/0! | H31: =H30/H13 -> #DIV/0! | I31: =I30/I13 -> #DIV/0! | J31: =J30/J13 -> #DIV/0! | K31: =K30/K13 -> 0.23613121 | L31: =L30/L13 -> #DIV/0! | M31: =M30/M13 -> #DIV/0! | ... AR31: =AR30/AR13 -> 0.085671194
E32: Depreciation & Amortization | F32: 387 | K32: 412 | P32: 456 | U32: 439 | Z32: =AVERAGE(F32,K32,P32,U32) -> 423.5 | AE32: =AVERAGE(F32:Z32) -> 423.5 | AF32: =AVERAGE(G32:AA32) -> 432.625 | AG32: =AVERAGE(H32:AB32) -> 432.625 | AH32: =AVERAGE(I32:AC32) -> 432.625 | AI32: =AVERAGE(J32:AD32) -> 432.625 | AJ32: =AVERAGE(F32:AE32) -> 423.5 | AO32: =AVERAGE(F32:AJ32) -> 426.81818 | AP32: =AVERAGE(G32:AK32) -> 430.8 | AQ32: =AVERAGE(H32:AL32) -> 430.8 | AR32: =AVERAGE(I32:AM32) -> 430.8
E33: EBIT | F33: =F23-F32 -> 64 | G33: =G23-G32 -> 0 | H33: =H23-H32 -> 0 | I33: =I23-I32 -> 0 | J33: =J23-J32 -> 0 | K33: =K23-K32 -> -42 | L33: =L23-L32 -> 0 | M33: =M23-M32 -> 0 | ... Y33: =Y23-Y32 -> 0 | Z33: =Z30-Z32 -> 87.953692 | AA33: =AA30-AA32 -> #DIV/0! | AB33: =AB30-AB32 -> #DIV/0! | AC33: =AC30-AC32 -> #DIV/0! | AD33: =AD30-AD32 -> #DIV/0! | AE33: =AE30-AE32 -> 65.087092 | AF33: =AF30-AF32 -> #DIV/0! | AG33: =AG30-AG32 -> #DIV/0! | ... AR33: =AR30-AR32 -> 158.54844
E34: Margin % | F34: =F33/F13 -> 0.016985138 | G34: =G33/G13 -> #DIV/0! | H34: =H33/H13 -> #DIV/0! | I34: =I33/I13 -> #DIV/0! | J34: =J33/J13 -> #DIV/0! | K34: =K33/K13 -> -0.010130246 | L34: =L33/L13 -> #DIV/0! | M34: =M33/M13 -> #DIV/0! | ... AR34: =AR33/AR13 -> 0.023047544
E35: Adjusted EBIT | F35: =F30-F32 -> 966 | G35: =G30-G32 -> 0 | H35: =H30-H32 -> 0 | I35: =I30-I32 -> 0 | J35: =J30-J32 -> 0 | K35: =K30-K32 -> 567 | L35: =L30-L32 -> 0 | M35: =M30-M32 -> 0 | ... AR35: =AR30-AR32 -> 158.54844
E36: Margin % | F36: =F35/F13 -> 0.25636943 | G36: =G35/G13 -> #DIV/0! | H36: =H35/H13 -> #DIV/0! | I36: =I35/I13 -> #DIV/0! | J36: =J35/J13 -> #DIV/0! | K36: =K35/K13 -> 0.13675832 | L36: =L35/L13 -> #DIV/0! | M36: =M35/M13 -> #DIV/0! | ... AR36: =AR35/AR13 -> 0.023047544
E37: Interest Expense, net | F37: =146-6-6 -> 134 | K37: =283-15+28 -> 296 | P37: =399-15+12 -> 396 | U37: =421-12+6+15 -> 430 | Z37: 365 | AE37: 314 | AJ37: 235 | AO37: 75 | AP37: 75 | AQ37: 75 | AR37: 75
E38: As % of Beg Cash
E39: Earnings Before Tax | F39: =F35-F37 -> 832 | G39: =G35-G37 -> 0 | H39: =H35-H37 -> 0 | I39: =I35-I37 -> 0 | J39: =J35-J37 -> 0 | K39: =K35-K37 -> 271 | L39: =L35-L37 -> 0 | M39: =M35-M37 -> 0 | ... AR39: =AR35-AR37 -> 83.548439
E40: Income Tax | F40: 58 | K40: 82 | P40: 71 | U40: 35 | Z40: =Z39*0.2 -> -55.409262 | AA40: =AA39*0.2 -> #DIV/0! | AB40: =AB39*0.2 -> #DIV/0! | AC40: =AC39*0.2 -> #DIV/0! | AD40: =AD39*0.2 -> #DIV/0! | AE40: =AE39*0.2 -> -49.782582 | AF40: =AF39*0.2 -> #DIV/0! | AG40: =AG39*0.2 -> #DIV/0! | ... AR40: =AR39*0.2 -> 16.709688
E41: Tax Rate % | F41: =F40/F39 -> 0.069711538 | G41: =G40/G39 -> #DIV/0! | H41: =H40/H39 -> #DIV/0! | I41: =I40/I39 -> #DIV/0! | J41: =J40/J39 -> #DIV/0! | K41: =K40/K39 -> 0.30258303 | L41: =L40/L39 -> #DIV/0! | M41: =M40/M39 -> #DIV/0! | ... AR41: =AR40/AR39 -> 0.2
...

Sheet Segment
B2: Scenario | E2: Revenue & Operations
B3: 1 | E3: Bausch + Lomb (BCLO) | F3: 44979 | G3: =EOMONTH(F3,3) -> 45077 | H3: =EOMONTH(G3,3) -> 45169 | I3: =EOMONTH(H3,3) -> 45260 | J3: =EOMONTH(I3,3) -> 45351 | K3: =J3 -> 45351 | L3: =EOMONTH(K3,3) -> 45443 | M3: =EOMONTH(L3,3) -> 45535 | N3: =EOMONTH(M3,3) -> 45626 | O3: =EOMONTH(N3,3) -> 45716 | P3: =O3 -> 45716 | Q3: =EOMONTH(P3,3) -> 45808 | R3: =EOMONTH(Q3,3) -> 45900 | S3: =EOMONTH(R3,3) -> 45991 | T3: =EOMONTH(S3,3) -> 46081 | U3: =T3 -> 46081 | V3: =EOMONTH(U3,3) -> 46173 | W3: =EOMONTH(V3,3) -> 46265 | X3: =EOMONTH(W3,3) -> 46356 | Y3: =EOMONTH(X3,3) -> 46446 | Z3: =Y3 -> 46446 | AA3: =EOMONTH(Z3,3) -> 46538 | AB3: =EOMONTH(AA3,3) -> 46630 | AC3: =EOMONTH(AB3,3) -> 46721 | AD3: =EOMONTH(AC3,3) -> 46812 | AE3: =AD3 -> 46812 | AF3: =EOMONTH(AE3,3) -> 46904 | AG3: =EOMONTH(AF3,3) -> 46996 | AH3: =EOMONTH(AG3,3) -> 47087 | AI3: =EOMONTH(AH3,3) -> 47177 | AJ3: =AI3 -> 47177 | AK3: =EOMONTH(AJ3,3) -> 47269 | AL3: =EOMONTH(AK3,3) -> 47361 | AM3: =EOMONTH(AL3,3) -> 47452 | AN3: =EOMONTH(AM3,3) -> 47542 | AO3: =AN3 -> 47542 | AP3: 47999 | AQ3: 48335 | AR3: 48335
E4: $millions | F4: =YEAR(F3)-1&"A" -> 2022A | G4: ="Q1 "& YEAR(G3) -> Q1 2023 | H4: ="Q2 "& YEAR(H3) -> Q2 2023 | I4: ="Q3 "& YEAR(I3) -> Q3 2023 | J4: ="Q4 "& YEAR(J3)-1 -> Q4 2023 | K4: =YEAR(K3)-1&"A" -> 2023A | L4: ="Q1 "& YEAR(L3) -> Q1 2024 | M4: ="Q2 "& YEAR(M3) -> Q2 2024 | N4: ="Q3 "& YEAR(N3) -> Q3 2024 | O4: ="Q4 "& YEAR(O3)-1 -> Q4 2024 | P4: =YEAR(P3)-1&"A" -> 2024A | Q4: ="Q1 "& YEAR(Q3) -> Q1 2025 | R4: ="Q2 "& YEAR(R3) -> Q2 2025 | S4: ="Q3 "& YEAR(S3) -> Q3 2025 | T4: ="Q4 "& YEAR(T3)-1 -> Q4 2025 | U4: =YEAR(U3)-1&"A" -> 2025A | V4: ="Q1 "& YEAR(V3) -> Q1 2026 | W4: ="Q2 "& YEAR(W3) -> Q2 2026 | X4: ="Q3 "& YEAR(X3) -> Q3 2026 | Y4: ="Q4 "& YEAR(Y3)-1 -> Q4 2026 | Z4: =YEAR(Z3)-1&"A" -> 2026A | AA4: ="Q1 "& YEAR(AA3) -> Q1 2027 | AB4: ="Q2 "& YEAR(AB3) -> Q2 2027 | AC4: ="Q3 "& YEAR(AC3) -> Q3 2027 | AD4: ="Q4 "& YEAR(AD3)-1 -> Q4 2027 | AE4: =YEAR(AE3)-1&"A" -> 2027A | AF4: ="Q1 "& YEAR(AF3) -> Q1 2028 | AG4: ="Q2 "& YEAR(AG3) -> Q2 2028 | AH4: ="Q3 "& YEAR(AH3) -> Q3 2028 | AI4: ="Q4 "& YEAR(AI3)-1 -> Q4 2028 | AJ4: =YEAR(AJ3)-1&"E" -> 2028E | AK4: ="Q1 "& YEAR(AK3) -> Q1 2029 | AL4: ="Q2 "& YEAR(AL3) -> Q2 2029 | AM4: ="Q3 "& YEAR(AM3) -> Q3 2029 | AN4: ="Q4 "& YEAR(AN3)-1 -> Q4 2029 | AO4: =YEAR(AO3)-1&"E" -> 2029E | AP4: =YEAR(AP3)-1&"E" -> 2030E | AQ4: =YEAR(AQ3)-1&"E" -> 2031E | AR4: =YEAR(AR3)-1&"E" -> 2031E
E5: Revenue Build
B6: 1 = Base | E6: Total Revenues | F6: =SUM(F8,F13,F18) -> 3768 | G6: =SUM(G8,G13,G18) -> 0 | H6: =SUM(H8,H13,H18) -> 0 | I6: =SUM(I8,I13,I18) -> 0 | J6: =SUM(J8,J13,J18) -> 0 | K6: =SUM(K8,K13,K18) -> 4146 | L6: =SUM(L8,L13,L18) -> 0 | M6: =SUM(M8,M13,M18) -> 0 | ... AR6: =SUM(AR8,AR13,AR18) -> 6879.1902
B7: 2 = Bear | E7: Total Comp YoY | F7: - | K7: =K6/F6-1 -> 0.10031847 | L7: =L6/G6-1 -> #DIV/0! | M7: =M6/H6-1 -> #DIV/0! | N7: =N6/I6-1 -> #DIV/0! | O7: =O6/J6-1 -> #DIV/0! | P7: =P6/K6-1 -> 0.15557164 | Q7: =Q6/L6-1 -> #DIV/0! | R7: =R6/M6-1 -> #DIV/0! | ... AO7: =AO6/AJ6-1 -> 0.049348819 | AP7: =AP6/AO6-1 -> 0.029388899 | AQ7: =AQ6/AP6-1 -> 0.02942977 | AR7: =AR6/AQ6-1 -> 0.029470654
B8: 3 = Bull | E8: Vision Care Revenue | F8: 2369 | K8: 2543 | P8: 2739 | U8: 2923 | Z8: =U8*(1+Z9) -> 3135.1132 | AA8: =V8*(1+AA9) -> 0 | AB8: =W8*(1+AB9) -> 0 | AC8: =X8*(1+AC9) -> 0 | AD8: =Y8*(1+AD9) -> 0 | AE8: =Z8*(1+AE9) -> 3291.8688 | AF8: =AA8*(1+AF9) -> 0 | AG8: =AB8*(1+AG9) -> 0 | ... AO8: =AJ8*(1+AO9) -> 3629.2854 | AP8: =AO8*(1+AP9) -> 3738.164 | AQ8: =AP8*(1+AQ9) -> 3850.3089 | AR8: =AQ8*(1+AR9) -> 3965.8181
E9: Comp YoY | F9: - | K9: =K8/F8-1 -> 0.073448713 | L9: =L8/G8-1 -> #DIV/0! | M9: =M8/H8-1 -> #DIV/0! | N9: =N8/I8-1 -> #DIV/0! | O9: =O8/J8-1 -> #DIV/0! | P9: =P8/K8-1 -> 0.077074322 | Q9: =Q8/L8-1 -> #DIV/0! | R9: =R8/M8-1 -> #DIV/0! | ... Y9: =Y8/T8-1 -> #DIV/0! | Z9: =CHOOSE(Scenario,Z10,Z11,Z12) -> 0.072566945 | AA9: =CHOOSE(Scenario,AA10,AA11,AA12) -> 0 | AB9: =CHOOSE(Scenario,AB10,AB11,AB12) -> 0 | AC9: =CHOOSE(Scenario,AC10,AC11,AC12) -> 0 | AD9: =CHOOSE(Scenario,AD10,AD11,AD12) -> 0 | AE9: =CHOOSE(Scenario,AE10,AE11,AE12) -> 0.05 | AF9: =CHOOSE(Scenario,AF10,AF11,AF12) -> 0 | AG9: =CHOOSE(Scenario,AG10,AG11,AG12) -> 0 | ... AR9: =CHOOSE(Scenario,AR10,AR11,AR12) -> 0.03
E10: Base Case | Z10: =AVERAGE(K9,P9,U9) -> 0.072566945 | AE10: 0.05 | AJ10: 0.05 | AO10: 0.05 | AP10: 0.03 | AQ10: 0.03 | AR10: 0.03
E11: Bear Case | Z11: -0.035 | AE11: -0.025 | AF11: -0.025 | AG11: -0.025 | AH11: -0.025 | AI11: -0.025 | AJ11: -0.025 | AK11: -0.025 | AL11: -0.025 | AM11: -0.025 | AN11: -0.025 | AO11: -0.025 | AP11: -0.015 | AQ11: -0.015 | AR11: -0.015
E12: Bull Case | Z12: 0.09 | AE12: 0.07 | AF12: 0.07 | AG12: 0.07 | AH12: 0.07 | AI12: 0.07 | AJ12: 0.07 | AK12: 0.07 | AL12: 0.07 | AM12: 0.07 | AN12: 0.07 | AO12: 0.07 | AP12: 0.04 | AQ12: 0.04 | AR12: 0.04
E13: Pharmaceutial Revenue | F13: 681 | K13: 836 | P13: 1209 | U13: 1284 | Z13: =U13*(1+Z14) -> 1361.04 | AA13: =V13*(1+AA14) -> 0 | AB13: =W13*(1+AB14) -> 0 | AC13: =X13*(1+AC14) -> 0 | AD13: =Y13*(1+AD14) -> 0 | AE13: =Z13*(1+AE14) -> 1415.4816 | AF13: =AA13*(1+AF14) -> 0 | AG13: =AB13*(1+AG14) -> 0 | ... AO13: =AJ13*(1+AO14) -> 1530.9849 | AP13: =AO13*(1+AP14) -> 1561.6046 | AQ13: =AP13*(1+AQ14) -> 1592.8367 | AR13: =AQ13*(1+AR14) -> 1624.6934
E14: Comp YoY | F14: - | K14: =K13/F13-1 -> 0.22760646 | L14: =L13/G13-1 -> #DIV/0! | M14: =M13/H13-1 -> #DIV/0! | N14: =N13/I13-1 -> #DIV/0! | O14: =O13/J13-1 -> #DIV/0! | P14: =P13/K13-1 -> 0.44617225 | Q14: =Q13/L13-1 -> #DIV/0! | R14: =R13/M13-1 -> #DIV/0! | ... Y14: =Y13/T13-1 -> #DIV/0! | Z14: =CHOOSE(Scenario,Z15,Z16,Z17) -> 0.06 | AA14: =CHOOSE(Scenario,AA15,AA16,AA17) -> 0 | AB14: =CHOOSE(Scenario,AB15,AB16,AB17) -> 0 | AC14: =CHOOSE(Scenario,AC15,AC16,AC17) -> 0 | AD14: =CHOOSE(Scenario,AD15,AD16,AD17) -> 0 | AE14: =CHOOSE(Scenario,AE15,AE16,AE17) -> 0.04 | AF14: =CHOOSE(Scenario,AF15,AF16,AF17) -> 0.04 | AG14: =CHOOSE(Scenario,AG15,AG16,AG17) -> 0.04 | ... AR14: =CHOOSE(Scenario,AR15,AR16,AR17) -> 0.02
E15: Base Case | Z15: 0.06 | AE15: 0.04 | AF15: 0.04 | AG15: 0.04 | AH15: 0.04 | AI15: 0.04 | AJ15: 0.04 | AK15: 0.04 | AL15: 0.04 | AM15: 0.04 | AN15: 0.04 | AO15: 0.04 | AP15: 0.02 | AQ15: 0.02 | AR15: 0.02
E16: Bear Case | Z16: -0.03 | AE16: -0.02 | AF16: -0.02 | AG16: -0.02 | AH16: -0.02 | AI16: -0.02 | AJ16: -0.02 | AK16: -0.02 | AL16: -0.02 | AM16: -0.02 | AN16: -0.02 | AO16: -0.02 | AP16: -0.01 | AQ16: -0.01 | AR16: -0.01
E17: Bull Case | Z17: 0.08 | AE17: 0.06 | AF17: 0.06 | AG17: 0.06 | AH17: 0.06 | AI17: 0.06 | AJ17: 0.06 | AK17: 0.06 | AL17: 0.06 | AM17: 0.06 | AN17: 0.06 | AO17: 0.06 | AP17: 0.04 | AQ17: 0.04 | AR17: 0.04
E18: Surgical Revenue | F18: 718 | K18: 767 | P18: 843 | U18: 894 | Z18: =U18*(1+Z19) -> 961.89355 | AA18: =V18*(1+AA19) -> 0 | AB18: =W18*(1+AB19) -> 0 | AC18: =X18*(1+AC19) -> 0 | AD18: =Y18*(1+AD19) -> 0 | AE18: =Z18*(1+AE19) -> 1019.6072 | AF18: =AA18*(1+AF19) -> 0 | AG18: =AB18*(1+AG19) -> 0 | ... AO18: =AJ18*(1+AO19) -> 1145.6306 | AP18: =AO18*(1+AP19) -> 1191.4558 | AQ18: =AP18*(1+AQ19) -> 1239.1141 | AR18: =AQ18*(1+AR19) -> 1288.6786
E19: Comp YoY | F19: - | K19: =K18/F18-1 -> 0.068245125 | L19: =L18/G18-1 -> #DIV/0! | M19: =M18/H18-1 -> #DIV/0! | N19: =N18/I18-1 -> #DIV/0! | O19: =O18/J18-1 -> #DIV/0! | P19: =P18/K18-1 -> 0.099087353 | Q19: =Q18/L18-1 -> #DIV/0! | R19: =R18/M18-1 -> #DIV/0! | ... Y19: =Y18/T18-1 -> #DIV/0! | Z19: =CHOOSE(Scenario,Z20,Z21,Z22) -> 0.075943566 | AA19: =CHOOSE(Scenario,AA20,AA21,AA22) -> 0 | AB19: =CHOOSE(Scenario,AB20,AB21,AB22) -> 0 | AC19: =CHOOSE(Scenario,AC20,AC21,AC22) -> 0 | AD19: =CHOOSE(Scenario,AD20,AD21,AD22) -> 0 | AE19: =CHOOSE(Scenario,AE20,AE21,AE22) -> 0.06 | AF19: =CHOOSE(Scenario,AF20,AF21,AF22) -> 0.06 | AG19: =CHOOSE(Scenario,AG20,AG21,AG22) -> 0.06 | ... AR19: =CHOOSE(Scenario,AR20,AR21,AR22) -> 0.04
E20: Base Case | Z20: =AVERAGE(K19,P19,U19) -> 0.075943566 | AE20: 0.06 | AF20: 0.06 | AG20: 0.06 | AH20: 0.06 | AI20: 0.06 | AJ20: 0.06 | AK20: 0.06 | AL20: 0.06 | AM20: 0.06 | AN20: 0.06 | AO20: 0.06 | AP20: 0.04 | AQ20: 0.04 | AR20: 0.04
E21: Bear Case | Z21: -0.04 | AE21: -0.03 | AF21: -0.03 | AG21: -0.03 | AH21: -0.03 | AI21: -0.03 | AJ21: -0.03 | AK21: -0.03 | AL21: -0.03 | AM21: -0.03 | AN21: -0.03 | AO21: -0.03 | AP21: -0.03 | AQ21: -0.03 | AR21: -0.03
E22: Bull Case | Z22: 0.1 | AE22: 0.08 | AF22: 0.08 | AG22: 0.08 | AH22: 0.08 | AI22: 0.08 | AJ22: 0.08 | AK22: 0.08 | AL22: 0.08 | AM22: 0.08 | AN22: 0.08 | AO22: 0.08 | AP22: 0.08 | AQ22: 0.08 | AR22: 0.08
E24: COGS Build
E25: Total Cost of Goods Sold | F25: =F26 -> 1511 | G25: =G26 -> 0 | H25: =H26 -> 0 | I25: =I26 -> 0 | J25: =J26 -> 0 | K25: =K26 -> 1640 | L25: =L26 -> 0 | M25: =M26 -> 0 | ... AR25: =AR26 -> 2751.6761
E26: Cost of Good Sold (Operating Cost) | F26: 1511 | K26: 1640 | P26: 1868 | U26: 2045 | Z26: =Z27*Z6 -> 2183.2187 | AA26: =AA27*AA6 -> 0 | AB26: =AB27*AB6 -> 0 | AC26: =AC27*AC6 -> 0 | AD26: =AD27*AD6 -> 0 | AE26: =AE27*AE6 -> 2290.783 | AF26: =AF27*AF6 -> 0 | AG26: =AG27*AG6 -> 0 | ... AR26: =AR27*AR6 -> 2751.6761
E27: Gross Margin % | F27: =F26/F6 -> 0.40100849 | G27: =G26/G6 -> #DIV/0! | H27: =H26/H6 -> #DIV/0! | I27: =I26/I6 -> #DIV/0! | J27: =J26/J6 -> #DIV/0! | K27: =K26/K6 -> 0.39556199 | L27: =L26/L6 -> #DIV/0! | M27: =M26/M6 -> #DIV/0! | ... U27: =U26/U6 -> 0.40090178 | Z27: =CHOOSE(Scenario,Z28,Z29,Z30) -> 0.4 | AA27: =CHOOSE(Scenario,AA28,AA29,AA30) -> 0.4 | AB27: =CHOOSE(Scenario,AB28,AB29,AB30) -> 0.4 | AC27: =CHOOSE(Scenario,AC28,AC29,AC30) -> 0.4 | AD27: =CHOOSE(Scenario,AD28,AD29,AD30) -> 0.4 | AE27: =CHOOSE(Scenario,AE28,AE29,AE30) -> 0.4 | AF27: =CHOOSE(Scenario,AF28,AF29,AF30) -> 0.4 | AG27: =CHOOSE(Scenario,AG28,AG29,AG30) -> 0.4 | ... AR27: =CHOOSE(Scenario,AR28,AR29,AR30) -> 0.4
E28: Base Case | Z28: 0.4 | AA28: 0.4 | AB28: 0.4 | AC28: 0.4 | AD28: 0.4 | AE28: 0.4 | AF28: 0.4 | AG28: 0.4 | AH28: 0.4 | AI28: 0.4 | AJ28: 0.4 | AK28: 0.4 | AL28: 0.4 | AM28: 0.4 | AN28: 0.4 | AO28: 0.4 | AP28: 0.4 | AQ28: 0.4 | AR28: 0.4
E29: Bear Case | Z29: 0.37 | AA29: 0.37 | AB29: 0.37 | AC29: 0.37 | AD29: 0.37 | AE29: 0.37 | AF29: 0.37 | AG29: 0.37 | AH29: 0.37 | AI29: 0.37 | AJ29: 0.37 | AK29: 0.37 | AL29: 0.37 | AM29: 0.37 | AN29: 0.37 | AO29: 0.37 | AP29: 0.37 | AQ29: 0.37 | AR29: 0.37
E30: Bull Case | Z30: 0.42 | AA30: 0.42 | AB30: 0.42 | AC30: 0.42 | AD30: 0.42 | AE30: 0.42 | AF30: 0.42 | AG30: 0.42 | AH30: 0.42 | AI30: 0.42 | AJ30: 0.42 | AK30: 0.42 | AL30: 0.42 | AM30: 0.42 | AN30: 0.42 | AO30: 0.42 | AP30: 0.42 | AQ30: 0.42 | AR30: 0.42

Sheet Industry & Scenario
B2: Industry Comparables
B3: Company Info | G3: Stock Returns | J3: NTM Valuation | L3: Profitability
B4: Name | C4: Ticker | D4: Price | E4: Mcap ($m) | F4: EV ($m) | G4: 6-Month | H4: 1-Year | I4: YTD | J4: EV/EBITDA | K4: P/E | L4: EBITDA Margin | M4: ROIC
B5: Bausch + Lomb | C5: BCLO | D5: =Data!F49 -> 16.82 | E5: =BCLO!Z101 -> 5905.5854 | F5: =BCLO!U103 -> 10635.916 | G5: 0.0086 | H5: 0.0026 | I5: 0.0046 | J5: =BCLO!Z93 -> 21.065415 | K5: =BCLO!Z92 -> -26.645299 | L5: =BCLO!Z31 -> 0.09370636 | M5: =BCLO!Z97 -> 0.011450296
B6: Alcon | C6: ALC | D6: 75 | E6: 37850 | F6: 45000 | G6: 0.0049 | H6: -0.2004 | I6: -0.0244 | J6: 30 | K6: 38 | L6: 0.26 | M6: 0.27
B7: The Cooper Companies | C7: COO | D7: 70 | E7: 14400 | F7: 19000 | G7: -0.1296 | H7: -0.2252 | I7: -0.2252 | J7: 15 | K7: 15 | L7: 0.27 | M7: 0.03
B8: Staar Surgical | C8: STAA | D8: 18 | E8: 900 | F8: 700 | G8: -0.035 | H8: 0.0742 | I8: 0.4178 | J8: -29 | K8: -15 | L8: =-34% -> -0.34 | M8: =-16% -> -0.16
B9: Median | G9: =MEDIAN(G5:G8) -> -0.01505 | H9: =MEDIAN(H5:H8) -> -0.0989 | I9: =MEDIAN(I5:I8) -> -0.0099 | J9: =MEDIAN(J5:J8) -> 18.032708 | K9: =MEDIAN(K5:K8) -> 0 | L9: =MEDIAN(L5:L8) -> 0.17685318 | M9: =MEDIAN(M5:M8) -> 0.020725148
B10: Average | G10: =AVERAGE(G5:G8) -> -0.037775 | H10: =AVERAGE(H5:H8) -> -0.0872 | I10: =AVERAGE(I5:I8) -> 0.0432 | J10: =AVERAGE(J5:J8) -> 9.2663539 | K10: =AVERAGE(K5:K8) -> 2.8386753 | L10: =AVERAGE(L5:L8) -> 0.07092659 | M10: =AVERAGE(M5:M8) -> 0.037862574

Sheet Data
A1: BLCO | B1: Date | C1: Open | D1: High | E1: Low | F1: Close | G1: Volume
A2: Average | B2: 44682 | C2: 18 | D2: 20.4 | E2: 15.9 | F2: 16.82 | G2: 28540000
A3: =AVERAGE(F2:F49) -> 16.691875 | B3: 44713 | C3: 16.7 | D3: 17.1 | E3: 13.5 | F3: 14.21 | G3: 19820000
A4: Median | B4: 44743 | C4: 14.3 | D4: 16.85 | E4: 13.8 | F4: 16.35 | G4: 16450000
A5: =MEDIAN(F2:F49) -> 16.82 | B5: 44774 | C5: 16.5 | D5: 18.1 | E5: 15.6 | F5: 16.9 | G5: 14230000
B6: 44805 | C6: 16.8 | D6: 17.2 | E6: 13.9 | F6: 14.1 | G6: 15670000
B7: 44835 | C7: 14.2 | D7: 16.8 | E7: 13.85 | F7: 16.45 | G7: 13980000
B8: 44866 | C8: 16.5 | D8: 18.2 | E8: 15.9 | F8: 17.85 | G8: 12760000
B9: 44896 | C9: 17.7 | D9: 18.5 | E9: 15.5 | F9: 15.96 | G9: 11340000
B10: 44927 | C10: 16.1 | D10: 18.6 | E10: 15.8 | F10: 18.2 | G10: 14120000
B11: 44958 | C11: 18.1 | D11: 19.4 | E11: 17.2 | F11: 18.65 | G11: 11890000
B12: 44986 | C12: 18.7 | D12: 20.1 | E12: 17.9 | F12: 19.5 | G12: 13450000
B13: 45017 | C13: 19.6 | D13: 20.5 | E13: 18.4 | F13: 19.8 | G13: 10230000
B14: 45047 | C14: 19.9 | D14: 20.8 | E14: 18.2 | F14: 19.2 | G14: 12340000
B15: 45078 | C15: 19.3 | D15: 20.4 | E15: 18.1 | F15: 19.85 | G15: 11780000
B16: 45108 | C16: 19.9 | D16: 21 | E16: 18.5 | F16: 18.9 | G16: 13560000
B17: 45139 | C17: 18.8 | D17: 19.5 | E17: 17.2 | F17: 17.45 | G17: 10890000
... B49: 46113 | C49: 16.07 | D49: 17.12 | E49: 15.89 | F49: 16.82 | G49: 3070000
