Workbook

Sheet 0000000

Sheet Base Revenue Driver
A1: Owen Purnomo
A2: MGM Resorts International
A3: NYSE: MGM
A4: Segment Revenue Driver
A5: Figures in USD mm
A6: Segment | B6: Metrics | C6: 2020 | D6: 2021 | E6: 2022 | F6: 2023 | G6: 2024 | H6: 2025 | I6: 2026 | J6: 2027 | K6: 2028 | L6: 2029 | M6: 2030 | N6: 2031
A7: Las Vegas Strip Resorts | B7: Las Vegas Visitor Growth% | C7: - | D7: - | E7: - | F7: - | G7: - | H7: - | I7: 0 | J7: 0.015 | K7: =$J$7 -> 0.015 | L7: =$J$7 -> 0.015 | M7: =$J$7 -> 0.015 | N7: =$J$7 -> 0.015
B8: Spend per Visitor Growth % | C8: - | D8: - | E8: - | F8: - | G8: - | H8: - | I8: 0.005 | J8: 0.02 | K8: =$J$8 -> 0.02 | L8: =$J$8 -> 0.02 | M8: =$J$8 -> 0.02 | N8: =$J$8 -> 0.02
B9: Event Based Growth% | C9: - | D9: - | E9: - | F9: - | G9: - | H9: - | I9: 0 | J9: 0.005 | K9: 0 | L9: 0.0075 | M9: 0 | N9: 0
B10: Total Growth | C10: - | D10: - | E10: - | F10: - | G10: - | H10: - | I10: =SUM(I7:I9) -> 0.005 | J10: =SUM(J7:J9) -> 0.04 | K10: =SUM(K7:K9) -> 0.035 | L10: =SUM(L7:L9) -> 0.0425 | M10: =SUM(M7:M9) -> 0.035 | N10: =SUM(N7:N9) -> 0.035
A12: Casino
A13: Table Games | B13: Table Drop | C13: 2001 | D13: 3587 | E13: 5804 | F13: 6215 | G13: 6028 | H13: 6127 | I13: =H13*(1+I10) -> 6157.635 | J13: =I13*(1+J10) -> 6403.9404 | K13: =J13*(1+K10) -> 6628.0783 | L13: =K13*(1+L10) -> 6909.7716 | M13: =L13*(1+M10) -> 7151.6136 | N13: =M13*(1+N10) -> 7401.9201
B14: Table Drop Growth% | C14: =(C13-3526)/3526 -> -0.43250142 | D14: =(D13-C13)/C13 -> 0.7926037 | E14: =(E13-D13)/D13 -> 0.61806524 | F14: =(F13-E13)/E13 -> 0.070813232 | G14: =(G13-F13)/F13 -> -0.030088496 | H14: =(H13-G13)/G13 -> 0.016423358 | I14: =(I13-H13)/H13 -> 0.005 | J14: =(J13-I13)/I13 -> 0.04 | K14: =(K13-J13)/J13 -> 0.035 | ... N14: =(N13-M13)/M13 -> 0.035
B15: Table Win% | C15: 0.235 | D15: 0.246 | E15: 0.24 | F15: 0.263 | G15: 0.244 | H15: 0.252 | I15: =AVERAGE(C15:H15) -> 0.24666667 | J15: =$I$15 -> 0.24666667 | K15: =$I$15 -> 0.24666667 | L15: =$I$15 -> 0.24666667 | M15: =$I$15 -> 0.24666667 | N15: =$I$15 -> 0.24666667
B16: Table Win | C16: =C13*C15 -> 470.235 | D16: =D13*D15 -> 882.402 | E16: =E13*E15 -> 1392.96 | F16: =F13*F15 -> 1634.545 | G16: =G13*G15 -> 1470.832 | H16: =H13*H15 -> 1544.004 | I16: =I13*I15 -> 1518.8833 | J16: =J13*J15 -> 1579.6386 | ... N16: =N13*N15 -> 1825.807
A18: Slot Games | B18: Slot Handle | C18: 6904 | D18: 15089 | E18: 22812 | F18: 23920 | G18: 23840 | H18: 24565 | I18: =H18*(1+I10) -> 24687.825 | J18: =I18*(1+J10) -> 25675.338 | K18: =J18*(1+K10) -> 26573.975 | L18: =K18*(1+L10) -> 27703.369 | M18: =L18*(1+M10) -> 28672.987 | N18: =M18*(1+N10) -> 29676.541
B19: Slot Handle Growth% | C19: =(C18-12874)/12874 -> -0.46372534 | D19: =(D18-C18)/C18 -> 1.1855446 | E19: =(E18-D18)/D18 -> 0.51182981 | F19: =(F18-E18)/E18 -> 0.048570928 | G19: =(G18-F18)/F18 -> -0.0033444816 | H19: =(H18-G18)/G18 -> 0.030411074 | I19: =(I18-H18)/H18 -> 0.005 | J19: =(J18-I18)/I18 -> 0.04 | K19: =(K18-J18)/J18 -> 0.035 | ... N19: =(N18-M18)/M18 -> 0.035
B20: Slot Win% | C20: 0.094 | D20: 0.094 | E20: 0.093 | F20: 0.093 | G20: 0.094 | H20: 0.094 | I20: =AVERAGE(C20:H20) -> 0.093666667 | J20: =$I$20 -> 0.093666667 | K20: =$I$20 -> 0.093666667 | L20: =$I$20 -> 0.093666667 | M20: =$I$20 -> 0.093666667 | N20: =$I$20 -> 0.093666667
B21: Slot Win | C21: =C18*C20 -> 648.976 | D21: =D18*D20 -> 1418.366 | E21: =E18*E20 -> 2121.516 | F21: =F18*F20 -> 2224.56 | G21: =G18*G20 -> 2240.96 | H21: =H18*H20 -> 2309.11 | I21: =I18*I20 -> 2312.4263 | J21: =J18*J20 -> 2404.9233 | ... N21: =N18*N20 -> 2779.7027
A23: Gaming Summary | B23: Total Handle | C23: =C13+C18 -> 8905 | D23: =D13+D18 -> 18676 | E23: =E13+E18 -> 28616 | F23: =F13+F18 -> 30135 | G23: =G13+G18 -> 29868 | H23: =H13+H18 -> 30692 | I23: =I13+I18 -> 30845.46 | J23: =J13+J18 -> 32079.278 | ... N23: =N13+N18 -> 37078.461
B24: Gross Gaming Win | C24: =C16+C21 -> 1119.211 | D24: =D16+D21 -> 2300.768 | E24: =E16+E21 -> 3514.476 | F24: =F16+F21 -> 3859.105 | G24: =G16+G21 -> 3711.792 | H24: =H16+H21 -> 3853.114 | I24: =I16+I21 -> 3831.3096 | J24: =J16+J21 -> 3984.562 | ... N24: =N16+N21 -> 4605.5097
B25: Gaming Incentives (SSP Allocation) | C25: 422.421 | D25: 752 | E25: 1410 | F25: 1731 | G25: 1752 | H25: 1839 | I25: =H25*(1+I26) -> 1848.195 | J25: =I25*(1+J26) -> 1922.1228 | K25: =J25*(1+K26) -> 1989.3971 | L25: =K25*(1+L26) -> 2073.9465 | M25: =L25*(1+M26) -> 2146.5346 | N25: =M25*(1+N26) -> 2221.6633
B26: Gaming Incentives Growth% | C26: =(C25-751)/751 -> -0.43752197 | D26: =(D25-C25)/C25 -> 0.78021453 | E26: =(E25-D25)/D25 -> 0.875 | F26: =(F25-E25)/E25 -> 0.22765957 | G26: =(G25-F25)/F25 -> 0.012131716 | H26: =(H25-G25)/G25 -> 0.049657534 | I26: =I10 -> 0.005 | J26: =J10 -> 0.04 | K26: =K10 -> 0.035 | L26: =L10 -> 0.0425 | M26: =M10 -> 0.035 | N26: =N10 -> 0.035
B27: Gaming Incentives (% of Gross Gaming Win) | C27: =C25/C24 -> 0.37742749 | D27: =D25/D24 -> 0.32684738 | E27: =E25/E24 -> 0.40119779 | F27: =F25/F24 -> 0.4485496 | G27: =G25/G24 -> 0.47200921 | H27: =H25/H24 -> 0.4772763 | I27: =I25/I24 -> 0.4823925 | J27: =J25/J24 -> 0.4823925 | ... N27: =N25/N24 -> 0.4823925 | P27: Despite stable hold rates and mix, rising promotional reinvestment has structurally diluted revenue conversion, indicating competitive pressure rather than demand weakness
B28: Casino Revenue | C28: =C24+31-C25 -> 727.79 | D28: =D24-D25 -> 1548.768 | E28: =E24-E25 -> 2104.476 | F28: =F24-F25 -> 2128.105 | G28: =G24-G25 -> 1959.792 | H28: =H24-H25 -> 2014.114 | I28: =I24-I25 -> 1983.1146 | J28: =J24-J25 -> 2062.4392 | K28: =K24-K25 -> 2134.6245 | ... N28: =N24-N25 -> 2383.8463
B29: Casino Revenue Growth% | C29: =(C28-1296)/1296 -> -0.43843364 | D29: =(D28-C28)/C28 -> 1.1280424 | E29: =(E28-D28)/D28 -> 0.35880648 | F29: =(F28-E28)/E28 -> 0.011227973 | G29: =(G28-F28)/F28 -> -0.079090552 | H29: =(H28-G28)/G28 -> 0.027718248 | I29: =(I28-H28)/H28 -> -0.015391098 | J29: =(J28-I28)/I28 -> 0.04 | K29: =(K28-J28)/J28 -> 0.035 | ... N29: =(N28-M28)/M28 -> 0.035
A31: Analytics | B31: Total SSP Allocation | C31: =C25 -> 422.421 | D31: =D25 -> 752 | E31: =E25 -> 1410 | F31: =F25 -> 1731 | G31: =G25 -> 1752 | H31: =H25 -> 1839 | I31: =I25 -> 1848.195 | J31: =J25 -> 1922.1228 | ... N31: =N25 -> 2221.6633 | P31: MGM retains only ~50% of gross gaming win as casino revenue, with the remainder reinvested into customer incentives and reallocated across non-gaming segments, materially distorting segment-level profitability.
B32: Rooms% of LVSR | C32: =C54/C67 -> 0.25778233 | D32: =D54/D67 -> 0.27516371 | E32: =E54/E67 -> 0.30261436 | F32: =F54/F67 -> 0.34174595 | G32: =G54/G67 -> 0.35634358 | H32: =H54/H67 -> 0.33850277 | I32: =I54/I67 -> 0.33741517 | J32: =J54/J67 -> 0.33308774 | ... N32: =N54/N67 -> 0.31867493
B33: SSP Allocation to Rooms | C33: =C31*C32 -> 108.89267 | D33: =D31*D32 -> 206.92311 | E33: =E31*E32 -> 426.68625 | F33: =F31*F32 -> 591.56224 | G33: =G31*G32 -> 624.31394 | H33: =H31*H32 -> 622.5066 | I33: =I31*I32 -> 623.60904 | J33: =J31*J32 -> 640.23555 | ... N33: =N31*N32 -> 707.9884
B34: F&B% of LVSR | C34: =C59/C67 -> 0.22100565 | D34: =D59/D67 -> 0.22075009 | E34: =E59/E67 -> 0.26148227 | F34: =F59/F67 -> 0.26108406 | G34: =G59/G67 -> 0.26817159 | H34: =H59/H67 -> 0.26887645 | I34: =I59/I67 -> 0.27131262 | J34: =J59/J67 -> 0.2730846 | ... N34: =N59/N67 -> 0.2789863
B35: SSP Allocation to Food and Beverage | C35: =C31*C34 -> 93.357426 | D35: =D31*D34 -> 166.00407 | E35: =E31*E34 -> 368.69 | F35: =F31*F34 -> 451.93651 | G35: =G31*G34 -> 469.83662 | H35: =H31*H34 -> 494.4638 | I35: =I31*I34 -> 501.43862 | J35: =J31*J34 -> 524.90213 | ... N35: =N31*N34 -> 619.81362
B36: Entertainmen% of LVSR | C36: =C64/C67 -> 0.17971372 | D36: =D64/D67 -> 0.1672481 | E36: =E64/E67 -> 0.17694659 | F36: =F64/F67 -> 0.15443767 | G36: =G64/G67 -> 0.15241161 | H36: =H64/H67 -> 0.15299784 | I36: =I64/I67 -> 0.15438408 | J36: =J64/J67 -> 0.15539238 | ... N36: =N64/N67 -> 0.15875061
B37: SSP Allocation to Entertainment and Other | C37: =C31*C36 -> 75.91485 | D37: =D31*D36 -> 125.77057 | E37: =E31*E36 -> 249.49469 | F37: =F31*F36 -> 267.3316 | G37: =G31*G36 -> 267.02514 | H37: =H31*H36 -> 281.36303 | I37: =I31*I36 -> 285.33189 | J37: =J31*J36 -> 298.68325 | ... N37: =N31*N36 -> 352.69041
B39: Blend Hold% | C39: =C24/C23 -> 0.12568344 | D39: =D24/D23 -> 0.12319383 | E39: =E24/E23 -> 0.12281507 | F39: =F24/F23 -> 0.12806056 | G39: =G24/G23 -> 0.1242732 | H39: =H24/H23 -> 0.12554131 | I39: =I24/I23 -> 0.12420984 | J39: =J24/J23 -> 0.12420984 | ... N39: =N24/N23 -> 0.12420984
B40: Table Mix% | C40: =C16/C24 -> 0.42014866 | D40: =D16/D24 -> 0.38352498 | E40: =E16/E24 -> 0.39634927 | F40: =F16/F24 -> 0.42355546 | G40: =G16/G24 -> 0.39625927 | H40: =H16/H24 -> 0.40071589 | I40: =I16/I24 -> 0.39643972 | J40: =J16/J24 -> 0.39643972 | ... N40: =N16/N24 -> 0.39643972
B41: Slot Mix% | C41: =C21/C24 -> 0.57985134 | D41: =D21/D24 -> 0.61647502 | E41: =E21/E24 -> 0.60365073 | F41: =F21/F24 -> 0.57644454 | G41: =G21/G24 -> 0.60374073 | H41: =H21/H24 -> 0.59928411 | I41: =I21/I24 -> 0.60356028 | J41: =J21/J24 -> 0.60356028 | ... N41: =N21/N24 -> 0.60356028
B42: Net Monetization | C42: =C28/C24 -> 0.65027059 | D42: =D28/D24 -> 0.67315262 | E42: =E28/E24 -> 0.59880221 | F42: =F28/F24 -> 0.5514504 | G42: =G28/G24 -> 0.52799079 | H42: =H28/H24 -> 0.5227237 | I42: =I28/I24 -> 0.5176075 | J42: =J28/J24 -> 0.5176075 | ... N42: =N28/N24 -> 0.5176075
B43: Promo/SSP Rate | C43: =1-C42 -> 0.34972941 | D43: =1-D42 -> 0.32684738 | E43: =1-E42 -> 0.40119779 | F43: =1-F42 -> 0.4485496 | G43: =1-G42 -> 0.47200921 | H43: =1-H42 -> 0.4772763 | I43: =1-I42 -> 0.4823925 | J43: =1-J42 -> 0.4823925 | ... N43: =1-N42 -> 0.4823925
A45: Rooms | B45: Occupancy% | C45: 0.55 | D45: 0.74 | E45: 0.89 | F45: 0.93 | G45: 0.94 | H45: 0.92 | I45: 0.9 | J45: =$I$45 -> 0.9 | K45: =$I$45 -> 0.9 | L45: =$I$45 -> 0.9 | M45: =$I$45 -> 0.9 | N45: =$I$45 -> 0.9
B46: Occupancy Growth% | C46: =(C45-91%)/91% -> -0.3956044 | D46: =(D45-C45)/C45 -> 0.34545455 | E46: =(E45-D45)/D45 -> 0.2027027 | F46: =(F45-E45)/E45 -> 0.04494382 | G46: =(G45-F45)/F45 -> 0.010752688 | H46: =(H45-G45)/G45 -> -0.021276596 | I46: =(I45-H45)/H45 -> -0.02173913 | J46: =(J45-I45)/I45 -> 0 | K46: =(K45-J45)/J45 -> 0 | ... N46: =(N45-M45)/M45 -> 0
...

Sheet Base MGM IS
A1: Owen Purnomo
A2: MGM
A3: NYSE: MGM
A4: Base Case Income Statement | B4: 2020 | C4: 2021 | D4: 2022 | E4: 2023 | F4: 2024 | G4: 2025 | H4: 2026 | I4: 2027 | J4: 2028 | K4: 2029 | L4: 2030 | M4: 2031
A5: Las Vegas Strip Resorts Revenue | B5: ='Base Revenue Driver'!C67 -> 2131.1673 | C5: ='Base Revenue Driver'!D67 -> 4597.9596 | D5: ='Base Revenue Driver'!E67 -> 8126.7461 | E5: ='Base Revenue Driver'!F67 -> 8767.2913 | F5: ='Base Revenue Driver'!G67 -> 8785.42 | G5: ='Base Revenue Driver'!H67 -> 8405.3474 | H5: ='Base Revenue Driver'!I67 -> 8371.5237 | I5: ='Base Revenue Driver'!J67 -> 8649.8911 | ... M5: ='Base Revenue Driver'!N67 -> 9786.3801
A6: Regional Operations Revenue | B6: ='Base Revenue Driver'!C125 -> 1967.171 | C6: ='Base Revenue Driver'!D125 -> 3305.433 | D6: ='Base Revenue Driver'!E125 -> 3670.91 | E6: ='Base Revenue Driver'!F125 -> 3670.309 | F6: ='Base Revenue Driver'!G125 -> 3720.322 | G6: ='Base Revenue Driver'!H125 -> 3772.333 | H6: ='Base Revenue Driver'!I125 -> 3746.8782 | I6: ='Base Revenue Driver'!J125 -> 3931.1999 | ... M6: ='Base Revenue Driver'!N125 -> 4424.6001
A7: MGM China Revenue | B7: ='Base Revenue Driver'!C176 -> 656.703 | C7: ='Base Revenue Driver'!D176 -> 1210.761 | D7: ='Base Revenue Driver'!E176 -> 673.593 | E7: ='Base Revenue Driver'!F176 -> 3153.609 | F7: ='Base Revenue Driver'!G176 -> 4022.384 | G7: ='Base Revenue Driver'!H176 -> 4461.743 | H7: ='Base Revenue Driver'!I176 -> 4268.2451 | I7: ='Base Revenue Driver'!J176 -> 4705.3844 | ... M7: ='Base Revenue Driver'!N176 -> 5719.4242
A8: MGM Digital Revenue | B8: ='Base Revenue Driver'!C190 -> 0 | C8: ='Base Revenue Driver'!D190 -> 0 | D8: ='Base Revenue Driver'!E190 -> 0 | E8: ='Base Revenue Driver'!F190 -> 432.146 | F8: ='Base Revenue Driver'!G190 -> 552.012 | G8: ='Base Revenue Driver'!H190 -> 654.19 | H8: ='Base Revenue Driver'!I190 -> 729.42185 | I8: ='Base Revenue Driver'!J190 -> 813.30536 | ... M8: ='Base Revenue Driver'!N190 -> 1257.0516
A9: Total Revenue | B9: =SUM(B5:B7) -> 4755.0413 | C9: =SUM(C5:C7) -> 9114.1536 | D9: =SUM(D5:D7) -> 12471.249 | E9: =SUM(E5:E7) -> 15591.209 | F9: =SUM(F5:F7) -> 16528.126 | G9: =SUM(G5:G7) -> 16639.423 | H9: =SUM(H5:H7) -> 16386.647 | I9: =SUM(I5:I7) -> 17286.475 | ... M9: =SUM(M5:M7) -> 19930.404
A10: Grotwh Rate | B10: =(B9/28590)-1 -> -0.83368166 | C10: =(C9/B9)-1 -> 0.91673491 | D10: =(D9/C9)-1 -> 0.3683387 | E10: =(E9/D9)-1 -> 0.25017223 | F10: =(F9/E9)-1 -> 0.060092622 | G10: =(G9/F9)-1 -> 0.006733821 | H10: =(H9/G9)-1 -> -0.015191414 | I10: =(I9/H9)-1 -> 0.054912291 | J10: =(J9/I9)-1 -> 0.03544585 | ... M10: =(M9/L9)-1 -> 0.0357465
A12: Las Vegas Strip EBIT | B12: ='Base Revenue Driver'!C70 -> -628.89426 | C12: ='Base Revenue Driver'!D70 -> 2141.5255 | D12: ='Base Revenue Driver'!E70 -> -349.61576 | E12: ='Base Revenue Driver'!F70 -> 1506.4587 | F12: ='Base Revenue Driver'!G70 -> 1517.5912 | G12: ='Base Revenue Driver'!H70 -> 1265.5169 | H12: ='Base Revenue Driver'!I70 -> 1381.6581 | I12: ='Base Revenue Driver'!J70 -> 1427.6006 | ... M12: ='Base Revenue Driver'!N70 -> 1615.1697
A13: Regional Operations EBIT | B13: ='Base Revenue Driver'!C128 -> -450.83079 | C13: ='Base Revenue Driver'!D128 -> 498.36023 | D13: ='Base Revenue Driver'!E128 -> 388.68688 | E13: ='Base Revenue Driver'!F128 -> 428.20055 | F13: ='Base Revenue Driver'!G128 -> 470.6898 | G13: ='Base Revenue Driver'!H128 -> 448.5751 | H13: ='Base Revenue Driver'!I128 -> 452.24382 | I13: ='Base Revenue Driver'!J128 -> 474.49123 | ... M13: ='Base Revenue Driver'!N128 -> 534.04406
A14: MGM China EBIT | B14: ='Base Revenue Driver'!C179 -> -459.16795 | C14: ='Base Revenue Driver'!D179 -> -238.16476 | D14: ='Base Revenue Driver'!E179 -> -369.37188 | E14: ='Base Revenue Driver'!F179 -> 261.14164 | F14: ='Base Revenue Driver'!G179 -> 359.62815 | G14: ='Base Revenue Driver'!H179 -> 357.93641 | H14: ='Base Revenue Driver'!I179 -> 359.1549 | I14: ='Base Revenue Driver'!J179 -> 395.93834 | ... M14: ='Base Revenue Driver'!N179 -> 481.26552
A15: MGM Digital EBIT | B15: ='Base Revenue Driver'!C193 -> 0 | C15: ='Base Revenue Driver'!D193 -> 0 | D15: ='Base Revenue Driver'!E193 -> 0 | E15: ='Base Revenue Driver'!F193 -> -115.4309 | F15: ='Base Revenue Driver'!G193 -> -177.06519 | G15: ='Base Revenue Driver'!H193 -> -214.24042 | H15: ='Base Revenue Driver'!I193 -> -109.41328 | I15: ='Base Revenue Driver'!J193 -> -73.197483 | ... M15: ='Base Revenue Driver'!N193 -> 50.282064
A16: Corporate Expense | B16: ='Base Revenue Driver'!C196 -> 896 | C16: ='Base Revenue Driver'!D196 -> -123.022 | D16: ='Base Revenue Driver'!E196 -> 1769.67 | E16: ='Base Revenue Driver'!F196 -> -189 | F16: ='Base Revenue Driver'!G196 -> -680 | G16: ='Base Revenue Driver'!H196 -> -856 | H16: ='Base Revenue Driver'!I196 -> -768 | I16: ='Base Revenue Driver'!J196 -> -768 | ... M16: ='Base Revenue Driver'!N196 -> -768
A17: Total EBIT | B17: =SUM(B12:B16) -> -642.893 | C17: =SUM(C12:C16) -> 2278.699 | D17: =SUM(D12:D16) -> 1439.3692 | E17: =SUM(E12:E16) -> 1891.37 | F17: =SUM(F12:F16) -> 1490.844 | G17: =SUM(G12:G16) -> 1001.788 | H17: =SUM(H12:H16) -> 1315.6436 | I17: =SUM(I12:I16) -> 1456.8327 | ... M17: =SUM(M12:M16) -> 1912.7614
A18: Adjusted EBIT | B18: ='Base Revenue Driver'!C200 -> -538.893 | C18: ='Base Revenue Driver'!D200 -> 784.699 | D18: ='Base Revenue Driver'!E200 -> 369.36924 | E18: ='Base Revenue Driver'!F200 -> 1492.37 | F18: ='Base Revenue Driver'!G200 -> 1490.844 | G18: ='Base Revenue Driver'!H200 -> 1373.788 | H18: ='Base Revenue Driver'!I200 -> 1315.6436 | I18: ='Base Revenue Driver'!J200 -> 1456.8327 | ... M18: ='Base Revenue Driver'!N200 -> 1912.7614
A20: Interest Expense | B20: 676.38 | C20: 799.593 | D20: 594.954 | E20: 460.293 | F20: 443.23 | G20: 419.042 | H20: =AVERAGE(E20:G20) -> 440.855 | I20: =$H$20 -> 440.855 | J20: =$H$20 -> 440.855 | K20: =$H$20 -> 440.855 | L20: =$H$20 -> 440.855 | M20: =$H$20 -> 440.855
A21: Non-operating items from unconsolidated affiliates | B21: -103.304 | C21: -83.243 | D21: -23.457 | E21: -1.032 | F21: -0.734 | G21: 1.135 | H21: 0 | I21: 0 | J21: 0 | K21: 0 | L21: 0 | M21: 0
A22: Other, net | B22: -89.361 | C22: 65.941 | D22: 82.838 | E22: 42.591 | F22: 70.573 | G22: -303.094 | H22: 0 | I22: 0 | J22: 0 | K22: 0 | L22: 0 | M22: 0
A23: Pre-Tax Income | B23: =B18-B20+B21+B22 -> -1407.938 | C23: =C18-C20+C21+C22 -> -32.196 | D23: =D18-D20+D21+D22 -> -166.20376 | E23: =E18-E20+E21+E22 -> 1073.636 | F23: =F18-F20+F21+F22 -> 1117.453 | G23: =G18-G20+G21+G22 -> 652.787 | H23: =H18-H20+H21+H22 -> 874.78856 | I23: =I18-I20+I21+I22 -> 1015.9777 | ... M23: =M18-M20+M21+M22 -> 1471.9064
A24: Tax Benefit | B24: 191.572 | C24: -253.415 | D24: -697.068 | E24: -157.839 | F24: -52.457 | G24: 240.093 | H24: =0 -> 0 | I24: =H24 -> 0 | J24: =I24 -> 0 | K24: =J24 -> 0 | L24: =K24 -> 0 | M24: =L24 -> 0
A25: Net income attributable to noncontrolling interests | B25: 287.183 | C25: 45.981 | D25: 1266.362 | E25: -172.744 | F25: -318.05 | G25: =-315.01 -> -315.01 | H25: 0 | I25: 0 | J25: 0 | K25: 0 | L25: 0 | M25: 0
A26: Adjusted Net Income | B26: =B23+B24+B25 -> -929.183 | C26: =C23+C24+C25 -> -239.63 | D26: =D23+D24+D25 -> 403.09024 | E26: =E23+E24+E25 -> 743.053 | F26: =F23+F24+F25 -> 746.946 | G26: =G23+G24+G25 -> 577.87 | H26: =H23+H24+H25 -> 874.78856 | I26: =I23+I24+I25 -> 1015.9777 | ... M26: =M23+M24+M25 -> 1471.9064
A28: Depreciation & Amort. | B28: 1210.556 | C28: 1150.61 | D28: 3482.05 | E28: 814.128 | F28: 831.097 | G28: 1017.794 | H28: =+G28*(1+H10) -> 1002.3323 | I28: =+H28*(1+I10) -> 1057.3726 | J28: =+I28*(1+J10) -> 1094.8521 | K28: =+J28*(1+K10) -> 1136.5093 | L28: =+K28*(1+L10) -> 1177.0211 | M28: =+L28*(1+M10) -> 1219.0955
A29: Adjusted EBITDA | B29: =B28+B18 -> 671.663 | C29: =C28+C18 -> 1935.309 | D29: =D28+D18 -> 3851.4192 | E29: =E28+E18 -> 2306.498 | F29: =F28+F18 -> 2321.941 | G29: =G28+G18 -> 2391.582 | H29: =H28+H18 -> 2317.9758 | I29: =I28+I18 -> 2514.2053 | ... M29: =M28+M18 -> 3131.8569
A30: EBITDA Margin | B30: =B29/B9 -> 0.14125282 | C30: =C29/C9 -> 0.21234106 | D30: =D29/D9 -> 0.30882386 | E30: =E29/E9 -> 0.1479358 | F30: =F29/F9 -> 0.14048423 | G30: =G29/G9 -> 0.14372986 | H30: =H29/H9 -> 0.14145516 | I30: =I29/I9 -> 0.14544349 | ... M30: =M29/M9 -> 0.15713965
A31: Cash Interest | B31: =B52*B49 -> 816.8655 | C31: =C52*C49 -> 804.56418 | D31: =D52*D49 -> 595.13126 | E31: =E52*E49 -> 445.97262 | F31: =F52*F49 -> 343.55621 | G31: =G52*G49 -> 373.81206 | H31: =H52*H49 -> 293.00692 | I31: =I52*I49 -> 218.0786 | ... M31: =M52*M49 -> 142.87262
A32: Capex | B32: 271 | C32: 491 | D32: 765 | E32: 932 | F32: 1200 | G32: =1100 -> 1100 | H32: =1050 -> 1050 | I32: =$H$32 -> 1050 | J32: =$H$32 -> 1050 | K32: =$H$32 -> 1050 | L32: =$H$32 -> 1050 | M32: =$H$32 -> 1050
A33: Cash Taxes | B33: =B20 -> 676.38 | C33: =C20 -> 799.593 | D33: =D20 -> 594.954 | E33: =E20 -> 460.293 | F33: =F20 -> 443.23 | G33: =G20 -> 419.042 | H33: =H20 -> 440.855 | I33: =I20 -> 440.855 | ... M33: =M20 -> 440.855
A34: FCF | B34: =B29-B31-B32-B33 -> -1092.5825 | C34: =C29-C31-C32-C33 -> -159.84818 | D34: =D29-D31-D32-D33 -> 1896.334 | E34: =E29-E31-E32-E33 -> 468.23238 | F34: =F29-F31-F32-F33 -> 335.15479 | G34: =G29-G31-G32-G33 -> 498.72794 | H34: =H29-H31-H32-H33 -> 534.11392 | I34: =I29-I31-I32-I33 -> 805.27171 | ... M34: =M29-M31-M32-M33 -> 1498.1292
A35: Maintence Capex (60%) | G35: =G32*0.6 -> 660
A36: Operating Cash before maturities | G36: =G29-G31-G35 -> 1357.7699
A38: Lease Expense | B38: 751.002 | C38: 870.779 | D38: 1986.853 | E38: 2306.64 | F38: 2300.373 | G38: =F38*(1+G10) -> 2315.8633 | H38: =G38*(1+H10) -> 2280.6821 | I38: =H38*(1+I10) -> 2405.9195 | J38: =I38*(1+J10) -> 2491.1994 | K38: =J38*(1+K10) -> 2585.9853 | L38: =K38*(1+L10) -> 2678.1647 | M38: =L38*(1+M10) -> 2773.8997
A40: Credit Matrix
A41: EBIT/Interest | B41: =B18/B20 -> -0.79673113 | C41: =C18/C20 -> 0.98137302 | D41: =D18/D20 -> 0.62083663 | E41: =E18/E20 -> 3.2422175 | F41: =F18/F20 -> 3.36359 | G41: =G18/G20 -> 3.2784017 | H41: =H18/H20 -> 2.9843 | I41: =I18/I20 -> 3.304562 | ... M41: =M18/M20 -> 4.3387539
A42: EBITDA/Interest | B42: =B29/B20 -> 0.99302611 | C42: =C29/C20 -> 2.4203676 | D42: =D29/D20 -> 6.473474 | E42: =E29/E20 -> 5.0109343 | F42: =F29/F20 -> 5.2386819 | G42: =G29/G20 -> 5.7072608 | H42: =H29/H20 -> 5.2579098 | I42: =I29/I20 -> 5.703021 | ... M42: =M29/M20 -> 7.104052
A43: (EBITDA - CAPEX)/Interest | B43: =(B29-B32)/B20 -> 0.59236376 | C43: =(C29-C32)/C20 -> 1.8063052 | D43: =(D29-D32)/D20 -> 5.1876603 | E43: =(E29-E32)/E20 -> 2.9861371 | F43: =(F29-F32)/F20 -> 2.531284 | G43: =(G29-G32)/G20 -> 3.0822256 | H43: =(H29-H32)/H20 -> 2.8761743 | I43: =(I29-I32)/I20 -> 3.3212855 | ... M43: =(M29-M32)/M20 -> 4.7223165
A44: Gross Debt/EBITDAR | B44: =B52/(B29+B38) -> 8.6996939 | C44: =C52/(C29+C38) -> 4.551126 | D44: =D52/(D29+D38) -> 1.3068743 | E44: =E52/(E29+E38) -> 1.611241 | F44: =F52/(F29+F38) -> 1.3763998 | G44: =G52/(G29+G38) -> 1.3234782 | H44: =H52/(H29+H38) -> 1.1799212 | I44: =I52/(I29+I38) -> 0.869094 | ... M44: =M52/(M29+M38) -> 0.3557661
A45: Adjusted Debt/EBITDAR | B45: =B58/(B29+B38) -> 14.597159 | C45: =C58/(C29+C38) -> 8.7571466 | D45: =D58/(D29+D38) -> 5.6145355 | E45: =E58/(E29+E38) -> 7.0581762 | F45: =F58/(F29+F38) -> 6.8014183 | G45: =G58/(G29+G38) -> 6.6262996 | H45: =H58/(H29+H38) -> 6.6283474 | I45: =I58/(I29+I38) -> 5.9566566 | ... M45: =M58/(M29+M38) -> 4.5933554
...

Sheet Downside Revenue Driver
A1: Owen Purnomo
A2: MGM Resorts International
A3: NYSE: MGM
A4: Segment Revenue Driver
A5: Figures in USD mm
A6: Segment | B6: Metrics | C6: 2020 | D6: 2021 | E6: 2022 | F6: 2023 | G6: 2024 | H6: 2025 | I6: 2026 | J6: 2027 | K6: 2028 | L6: 2029 | M6: 2030 | N6: 2031
A7: Las Vegas Strip Resorts | B7: Las Vegas Visitor Growth% | C7: - | D7: - | E7: - | F7: - | G7: - | H7: - | I7: -0.03 | J7: -0.015 | K7: =0 -> 0 | L7: =0 -> 0 | M7: =0 -> 0 | N7: =0 -> 0
B8: Spend per Visitor Growth % | C8: - | D8: - | E8: - | F8: - | G8: - | H8: - | I8: -0.02 | J8: -0.015 | K8: =0 -> 0 | L8: =0 -> 0 | M8: =0 -> 0 | N8: =0 -> 0
B9: Event Based Growth% | C9: - | D9: - | E9: - | F9: - | G9: - | H9: - | I9: 0 | J9: 0 | K9: 0 | L9: 0.0075 | M9: 0 | N9: 0
B10: Total Growth | C10: - | D10: - | E10: - | F10: - | G10: - | H10: - | I10: =SUM(I7:I9) -> -0.05 | J10: =SUM(J7:J9) -> -0.03 | K10: =SUM(K7:K9) -> 0 | L10: =SUM(L7:L9) -> 0.0075 | M10: =SUM(M7:M9) -> 0 | N10: =SUM(N7:N9) -> 0
A12: Casino
A13: Table Games | B13: Table Drop | C13: 2001 | D13: 3587 | E13: 5804 | F13: 6215 | G13: 6028 | H13: 6127 | I13: =H13*(1+I10) -> 5820.65 | J13: =I13*(1+J10) -> 5646.0305 | K13: =J13*(1+K10) -> 5646.0305 | L13: =K13*(1+L10) -> 5688.3757 | M13: =L13*(1+M10) -> 5688.3757 | N13: =M13*(1+N10) -> 5688.3757
B14: Table Drop Growth% | C14: =(C13-3526)/3526 -> -0.43250142 | D14: =(D13-C13)/C13 -> 0.7926037 | E14: =(E13-D13)/D13 -> 0.61806524 | F14: =(F13-E13)/E13 -> 0.070813232 | G14: =(G13-F13)/F13 -> -0.030088496 | H14: =(H13-G13)/G13 -> 0.016423358 | I14: =(I13-H13)/H13 -> -0.05 | J14: =(J13-I13)/I13 -> -0.03 | K14: =(K13-J13)/J13 -> 0 | ... N14: =(N13-M13)/M13 -> 0
B15: Table Win% | C15: 0.235 | D15: 0.246 | E15: 0.24 | F15: 0.263 | G15: 0.244 | H15: 0.252 | I15: =AVERAGE(C15:H15) -> 0.24666667 | J15: =$I$15 -> 0.24666667 | K15: =$I$15 -> 0.24666667 | L15: =$I$15 -> 0.24666667 | M15: =$I$15 -> 0.24666667 | N15: =$I$15 -> 0.24666667
B16: Table Win | C16: =C13*C15 -> 470.235 | D16: =D13*D15 -> 882.402 | E16: =E13*E15 -> 1392.96 | F16: =F13*F15 -> 1634.545 | G16: =G13*G15 -> 1470.832 | H16: =H13*H15 -> 1544.004 | I16: =I13*I15 -> 1435.7603 | J16: =J13*J15 -> 1392.6875 | ... N16: =N13*N15 -> 1403.1327
A18: Slot Games | B18: Slot Handle | C18: 6904 | D18: 15089 | E18: 22812 | F18: 23920 | G18: 23840 | H18: 24565 | I18: =H18*(1+I10) -> 23336.75 | J18: =I18*(1+J10) -> 22636.647 | K18: =J18*(1+K10) -> 22636.647 | L18: =K18*(1+L10) -> 22806.422 | M18: =L18*(1+M10) -> 22806.422 | N18: =M18*(1+N10) -> 22806.422
B19: Slot Handle Growth% | C19: =(C18-12874)/12874 -> -0.46372534 | D19: =(D18-C18)/C18 -> 1.1855446 | E19: =(E18-D18)/D18 -> 0.51182981 | F19: =(F18-E18)/E18 -> 0.048570928 | G19: =(G18-F18)/F18 -> -0.0033444816 | H19: =(H18-G18)/G18 -> 0.030411074 | I19: =(I18-H18)/H18 -> -0.05 | J19: =(J18-I18)/I18 -> -0.03 | K19: =(K18-J18)/J18 -> 0 | ... N19: =(N18-M18)/M18 -> 0
B20: Slot Win% | C20: 0.094 | D20: 0.094 | E20: 0.093 | F20: 0.093 | G20: 0.094 | H20: 0.094 | I20: =AVERAGE(C20:H20) -> 0.093666667 | J20: =$I$20 -> 0.093666667 | K20: =$I$20 -> 0.093666667 | L20: =$I$20 -> 0.093666667 | M20: =$I$20 -> 0.093666667 | N20: =$I$20 -> 0.093666667
B21: Slot Win | C21: =C18*C20 -> 648.976 | D21: =D18*D20 -> 1418.366 | E21: =E18*E20 -> 2121.516 | F21: =F18*F20 -> 2224.56 | G21: =G18*G20 -> 2240.96 | H21: =H18*H20 -> 2309.11 | I21: =I18*I20 -> 2185.8756 | J21: =J18*J20 -> 2120.2993 | ... N21: =N18*N20 -> 2136.2016
A23: Gaming Summary | B23: Total Handle | C23: =C13+C18 -> 8905 | D23: =D13+D18 -> 18676 | E23: =E13+E18 -> 28616 | F23: =F13+F18 -> 30135 | G23: =G13+G18 -> 29868 | H23: =H13+H18 -> 30692 | I23: =I13+I18 -> 29157.4 | J23: =J13+J18 -> 28282.678 | ... N23: =N13+N18 -> 28494.798
B24: Gross Gaming Win | C24: =C16+C21 -> 1119.211 | D24: =D16+D21 -> 2300.768 | E24: =E16+E21 -> 3514.476 | F24: =F16+F21 -> 3859.105 | G24: =G16+G21 -> 3711.792 | H24: =H16+H21 -> 3853.114 | I24: =I16+I21 -> 3621.6359 | J24: =J16+J21 -> 3512.9868 | ... N24: =N16+N21 -> 3539.3342
B25: Gaming Incentives (SSP Allocation) | C25: 422.421 | D25: 752 | E25: 1410 | F25: 1731 | G25: 1752 | H25: 1839 | I25: =H25*(1+I26) -> 1747.05 | J25: =I25*(1+J26) -> 1694.6385 | K25: =J25*(1+K26) -> 1694.6385 | L25: =K25*(1+L26) -> 1707.3483 | M25: =L25*(1+M26) -> 1707.3483 | N25: =M25*(1+N26) -> 1707.3483
B26: Gaming Incentives Growth% | C26: =(C25-751)/751 -> -0.43752197 | D26: =(D25-C25)/C25 -> 0.78021453 | E26: =(E25-D25)/D25 -> 0.875 | F26: =(F25-E25)/E25 -> 0.22765957 | G26: =(G25-F25)/F25 -> 0.012131716 | H26: =(H25-G25)/G25 -> 0.049657534 | I26: =I10 -> -0.05 | J26: =J10 -> -0.03 | K26: =K10 -> 0 | L26: =L10 -> 0.0075 | M26: =M10 -> 0 | N26: =N10 -> 0
B27: Gaming Incentives (% of Gross Gaming Win) | C27: =C25/C24 -> 0.37742749 | D27: =D25/D24 -> 0.32684738 | E27: =E25/E24 -> 0.40119779 | F27: =F25/F24 -> 0.4485496 | G27: =G25/G24 -> 0.47200921 | H27: =H25/H24 -> 0.4772763 | I27: =I25/I24 -> 0.4823925 | J27: =J25/J24 -> 0.4823925 | ... N27: =N25/N24 -> 0.4823925 | P27: Despite stable hold rates and mix, rising promotional reinvestment has structurally diluted revenue conversion, indicating competitive pressure rather than demand weakness
B28: Casino Revenue | C28: =C24+31-C25 -> 727.79 | D28: =D24-D25 -> 1548.768 | E28: =E24-E25 -> 2104.476 | F28: =F24-F25 -> 2128.105 | G28: =G24-G25 -> 1959.792 | H28: =H24-H25 -> 2014.114 | I28: =I24-I25 -> 1874.5859 | J28: =J24-J25 -> 1818.3483 | K28: =K24-K25 -> 1818.3483 | ... N28: =N24-N25 -> 1831.986
B29: Casino Revenue Growth% | C29: =(C28-1296)/1296 -> -0.43843364 | D29: =(D28-C28)/C28 -> 1.1280424 | E29: =(E28-D28)/D28 -> 0.35880648 | F29: =(F28-E28)/E28 -> 0.011227973 | G29: =(G28-F28)/F28 -> -0.079090552 | H29: =(H28-G28)/G28 -> 0.027718248 | I29: =(I28-H28)/H28 -> -0.069275167 | J29: =(J28-I28)/I28 -> -0.03 | K29: =(K28-J28)/J28 -> 0 | ... N29: =(N28-M28)/M28 -> 0
A31: Analytics | B31: Total SSP Allocation | C31: =C25 -> 422.421 | D31: =D25 -> 752 | E31: =E25 -> 1410 | F31: =F25 -> 1731 | G31: =G25 -> 1752 | H31: =H25 -> 1839 | I31: =I25 -> 1747.05 | J31: =J25 -> 1694.6385 | ... N31: =N25 -> 1707.3483 | P31: MGM retains only ~50% of gross gaming win as casino revenue, with the remainder reinvested into customer incentives and reallocated across non-gaming segments, materially distorting segment-level profitability.
B32: Rooms% of LVSR | C32: =C54/C67 -> 0.25778233 | D32: =D54/D67 -> 0.27516371 | E32: =E54/E67 -> 0.30261436 | F32: =F54/F67 -> 0.34174595 | G32: =G54/G67 -> 0.35634358 | H32: =H54/H67 -> 0.33850277 | I32: =I54/I67 -> 0.32380574 | J32: =J54/J67 -> 0.33490682 | ... N32: =N54/N67 -> 0.35107066
B33: SSP Allocation to Rooms | C33: =C31*C32 -> 108.89267 | D33: =D31*D32 -> 206.92311 | E33: =E31*E32 -> 426.68625 | F33: =F31*F32 -> 591.56224 | G33: =G31*G32 -> 624.31394 | H33: =H31*H32 -> 622.5066 | I33: =I31*I32 -> 565.70481 | J33: =J31*J32 -> 567.54599 | ... N33: =N31*N32 -> 599.39989
B34: F&B% of LVSR | C34: =C59/C67 -> 0.22100565 | D34: =D59/D67 -> 0.22075009 | E34: =E59/E67 -> 0.26148227 | F34: =F59/F67 -> 0.26108406 | G34: =G59/G67 -> 0.26817159 | H34: =H59/H67 -> 0.26887645 | I34: =I59/I67 -> 0.27688535 | J34: =J59/J67 -> 0.27233973 | ... N34: =N59/N67 -> 0.26572102
B35: SSP Allocation to Food and Beverage | C35: =C31*C34 -> 93.357426 | D35: =D31*D34 -> 166.00407 | E35: =E31*E34 -> 368.69 | F35: =F31*F34 -> 451.93651 | G35: =G31*G34 -> 469.83662 | H35: =H31*H34 -> 494.4638 | I35: =I31*I34 -> 483.73256 | J35: =J31*J34 -> 461.51739 | ... N35: =N31*N34 -> 453.67833
B36: Entertainmen% of LVSR | C36: =C64/C67 -> 0.17971372 | D36: =D64/D67 -> 0.1672481 | E36: =E64/E67 -> 0.17694659 | F36: =F64/F67 -> 0.15443767 | G36: =G64/G67 -> 0.15241161 | H36: =H64/H67 -> 0.15299784 | I36: =I64/I67 -> 0.15755512 | J36: =J64/J67 -> 0.15496854 | ... N36: =N64/N67 -> 0.15120232
B37: SSP Allocation to Entertainment and Other | C37: =C31*C36 -> 75.91485 | D37: =D31*D36 -> 125.77057 | E37: =E31*E36 -> 249.49469 | F37: =F31*F36 -> 267.3316 | G37: =G31*G36 -> 267.02514 | H37: =H31*H36 -> 281.36303 | I37: =I31*I36 -> 275.25667 | J37: =J31*J36 -> 262.61565 | ... N37: =N31*N36 -> 258.15502
B39: Blend Hold% | C39: =C24/C23 -> 0.12568344 | D39: =D24/D23 -> 0.12319383 | E39: =E24/E23 -> 0.12281507 | F39: =F24/F23 -> 0.12806056 | G39: =G24/G23 -> 0.1242732 | H39: =H24/H23 -> 0.12554131 | I39: =I24/I23 -> 0.12420984 | J39: =J24/J23 -> 0.12420984 | ... N39: =N24/N23 -> 0.12420984
B40: Table Mix% | C40: =C16/C24 -> 0.42014866 | D40: =D16/D24 -> 0.38352498 | E40: =E16/E24 -> 0.39634927 | F40: =F16/F24 -> 0.42355546 | G40: =G16/G24 -> 0.39625927 | H40: =H16/H24 -> 0.40071589 | I40: =I16/I24 -> 0.39643972 | J40: =J16/J24 -> 0.39643972 | ... N40: =N16/N24 -> 0.39643972
B41: Slot Mix% | C41: =C21/C24 -> 0.57985134 | D41: =D21/D24 -> 0.61647502 | E41: =E21/E24 -> 0.60365073 | F41: =F21/F24 -> 0.57644454 | G41: =G21/G24 -> 0.60374073 | H41: =H21/H24 -> 0.59928411 | I41: =I21/I24 -> 0.60356028 | J41: =J21/J24 -> 0.60356028 | ... N41: =N21/N24 -> 0.60356028
B42: Net Monetization | C42: =C28/C24 -> 0.65027059 | D42: =D28/D24 -> 0.67315262 | E42: =E28/E24 -> 0.59880221 | F42: =F28/F24 -> 0.5514504 | G42: =G28/G24 -> 0.52799079 | H42: =H28/H24 -> 0.5227237 | I42: =I28/I24 -> 0.5176075 | J42: =J28/J24 -> 0.5176075 | ... N42: =N28/N24 -> 0.5176075
B43: Promo/SSP Rate | C43: =1-C42 -> 0.34972941 | D43: =1-D42 -> 0.32684738 | E43: =1-E42 -> 0.40119779 | F43: =1-F42 -> 0.4485496 | G43: =1-G42 -> 0.47200921 | H43: =1-H42 -> 0.4772763 | I43: =1-I42 -> 0.4823925 | J43: =1-J42 -> 0.4823925 | ... N43: =1-N42 -> 0.4823925
A45: Rooms | B45: Occupancy% | C45: 0.55 | D45: 0.74 | E45: 0.89 | F45: 0.93 | G45: 0.94 | H45: 0.92 | I45: 0.8 | J45: =$I$45 -> 0.8 | K45: =$I$45 -> 0.8 | L45: =$I$45 -> 0.8 | M45: =$I$45 -> 0.8 | N45: =$I$45 -> 0.8
B46: Occupancy Growth% | C46: =(C45-91%)/91% -> -0.3956044 | D46: =(D45-C45)/C45 -> 0.34545455 | E46: =(E45-D45)/D45 -> 0.2027027 | F46: =(F45-E45)/E45 -> 0.04494382 | G46: =(G45-F45)/F45 -> 0.010752688 | H46: =(H45-G45)/G45 -> -0.021276596 | I46: =(I45-H45)/H45 -> -0.13043478 | J46: =(J45-I45)/I45 -> 0 | K46: =(K45-J45)/J45 -> 0 | ... N46: =(N45-M45)/M45 -> 0
...

Sheet Downside MGM IS
A1: Owen Purnomo
A2: MGM
A3: NYSE: MGM
A4: Downside Case Income Statement | B4: 2020 | C4: 2021 | D4: 2022 | E4: 2023 | F4: 2024 | G4: 2025 | H4: 2026 | I4: 2027 | J4: 2028 | K4: 2029 | L4: 2030 | M4: 2031
A5: Las Vegas Strip Resorts Revenue | B5: ='Base Revenue Driver'!C67 -> 2131.1673 | C5: ='Base Revenue Driver'!D67 -> 4597.9596 | D5: ='Base Revenue Driver'!E67 -> 8126.7461 | E5: ='Base Revenue Driver'!F67 -> 8767.2913 | F5: ='Base Revenue Driver'!G67 -> 8785.42 | G5: ='Base Revenue Driver'!H67 -> 8405.3474 | H5: ='Downside Revenue Driver'!I67 -> 7754.1118 | I5: ='Downside Revenue Driver'!J67 -> 7647.0297 | J5: ='Downside Revenue Driver'!K67 -> 7698.2506 | K5: ='Downside Revenue Driver'!L67 -> 7788.6408 | L5: ='Downside Revenue Driver'!M67 -> 7841.9309 | M5: ='Downside Revenue Driver'!N67 -> 7896.2869
A6: Regional Operations Revenue | B6: ='Base Revenue Driver'!C125 -> 1967.171 | C6: ='Base Revenue Driver'!D125 -> 3305.433 | D6: ='Base Revenue Driver'!E125 -> 3670.91 | E6: ='Base Revenue Driver'!F125 -> 3670.309 | F6: ='Base Revenue Driver'!G125 -> 3720.322 | G6: ='Base Revenue Driver'!H125 -> 3772.333 | H6: ='Downside Revenue Driver'!I125 -> 3563.2077 | I6: ='Downside Revenue Driver'!J125 -> 3702.1979 | J6: ='Downside Revenue Driver'!K125 -> 3702.1979 | K6: ='Downside Revenue Driver'!L125 -> 3702.1979 | L6: ='Downside Revenue Driver'!M125 -> 3702.1979 | M6: ='Downside Revenue Driver'!N125 -> 3702.1979
A7: MGM China Revenue | B7: ='Base Revenue Driver'!C176 -> 656.703 | C7: ='Base Revenue Driver'!D176 -> 1210.761 | D7: ='Base Revenue Driver'!E176 -> 673.593 | E7: ='Base Revenue Driver'!F176 -> 3153.609 | F7: ='Base Revenue Driver'!G176 -> 4022.384 | G7: ='Base Revenue Driver'!H176 -> 4461.743 | H7: ='Downside Revenue Driver'!I176 -> 3917.7129 | I7: ='Downside Revenue Driver'!J176 -> 4010.4553 | J7: ='Downside Revenue Driver'!K176 -> 3870.0894 | K7: ='Downside Revenue Driver'!L176 -> 3734.6363 | L7: ='Downside Revenue Driver'!M176 -> 3603.924 | M7: ='Downside Revenue Driver'!N176 -> 3477.7867
A8: MGM Digital Revenue | B8: ='Base Revenue Driver'!C190 -> 0 | C8: ='Base Revenue Driver'!D190 -> 0 | D8: ='Base Revenue Driver'!E190 -> 0 | E8: ='Base Revenue Driver'!F190 -> 432.146 | F8: ='Base Revenue Driver'!G190 -> 552.012 | G8: ='Base Revenue Driver'!H190 -> 654.19 | H8: ='Downside Revenue Driver'!I190 -> 667.2738 | I8: ='Downside Revenue Driver'!J190 -> 680.61928 | J8: ='Downside Revenue Driver'!K190 -> 694.23166 | K8: ='Downside Revenue Driver'!L190 -> 708.11629 | L8: ='Downside Revenue Driver'!M190 -> 722.27862 | M8: ='Downside Revenue Driver'!N190 -> 736.72419
A9: Total Revenue | B9: =SUM(B5:B7) -> 4755.0413 | C9: =SUM(C5:C7) -> 9114.1536 | D9: =SUM(D5:D7) -> 12471.249 | E9: =SUM(E5:E7) -> 15591.209 | F9: =SUM(F5:F7) -> 16528.126 | G9: =SUM(G5:G7) -> 16639.423 | H9: =SUM(H5:H7) -> 15235.032 | I9: =SUM(I5:I7) -> 15359.683 | ... M9: =SUM(M5:M7) -> 15076.271
A10: Grotwh Rate | B10: =(B9/28590)-1 -> -0.83368166 | C10: =(C9/B9)-1 -> 0.91673491 | D10: =(D9/C9)-1 -> 0.3683387 | E10: =(E9/D9)-1 -> 0.25017223 | F10: =(F9/E9)-1 -> 0.060092622 | G10: =(G9/F9)-1 -> 0.006733821 | H10: =(H9/G9)-1 -> -0.084401421 | I10: =(I9/H9)-1 -> 0.0081818392 | J10: =(J9/I9)-1 -> -0.0058038365 | ... M10: =(M9/L9)-1 -> -0.004738653
A12: Las Vegas Strip EBIT | B12: ='Base Revenue Driver'!C70 -> -628.89426 | C12: ='Base Revenue Driver'!D70 -> 2141.5255 | D12: ='Base Revenue Driver'!E70 -> -349.61576 | E12: ='Base Revenue Driver'!F70 -> 1506.4587 | F12: ='Base Revenue Driver'!G70 -> 1517.5912 | G12: ='Base Revenue Driver'!H70 -> 1265.5169 | H12: ='Downside Revenue Driver'!I70 -> 775.41118 | I12: ='Downside Revenue Driver'!J70 -> 841.17327 | J12: ='Downside Revenue Driver'!K70 -> 923.79007 | K12: ='Downside Revenue Driver'!L70 -> 934.63689 | L12: ='Downside Revenue Driver'!M70 -> 941.03171 | M12: ='Downside Revenue Driver'!N70 -> 947.55443
A13: Regional Operations EBIT | B13: ='Base Revenue Driver'!C128 -> -450.83079 | C13: ='Base Revenue Driver'!D128 -> 498.36023 | D13: ='Base Revenue Driver'!E128 -> 388.68688 | E13: ='Base Revenue Driver'!F128 -> 428.20055 | F13: ='Base Revenue Driver'!G128 -> 470.6898 | G13: ='Base Revenue Driver'!H128 -> 448.5751 | H13: ='Downside Revenue Driver'!I128 -> 249.42454 | I13: ='Downside Revenue Driver'!J128 -> 296.17583 | J13: ='Downside Revenue Driver'!K128 -> 333.19781 | K13: ='Downside Revenue Driver'!L128 -> 333.19781 | L13: ='Downside Revenue Driver'!M128 -> 333.19781 | M13: ='Downside Revenue Driver'!N128 -> 333.19781
A14: MGM China EBIT | B14: ='Base Revenue Driver'!C179 -> -459.16795 | C14: ='Base Revenue Driver'!D179 -> -238.16476 | D14: ='Base Revenue Driver'!E179 -> -369.37188 | E14: ='Base Revenue Driver'!F179 -> 261.14164 | F14: ='Base Revenue Driver'!G179 -> 359.62815 | G14: ='Base Revenue Driver'!H179 -> 357.93641 | H14: ='Downside Revenue Driver'!I179 -> 156.70852 | I14: ='Base Revenue Driver'!J179 -> 395.93834 | J14: ='Base Revenue Driver'!K179 -> 415.73525 | K14: ='Base Revenue Driver'!L179 -> 436.52202 | L14: ='Base Revenue Driver'!M179 -> 458.34812 | M14: ='Base Revenue Driver'!N179 -> 481.26552
A15: MGM Digital EBIT | B15: ='Base Revenue Driver'!C193 -> 0 | C15: ='Base Revenue Driver'!D193 -> 0 | D15: ='Base Revenue Driver'!E193 -> 0 | E15: ='Base Revenue Driver'!F193 -> -115.4309 | F15: ='Base Revenue Driver'!G193 -> -177.06519 | G15: ='Base Revenue Driver'!H193 -> -214.24042 | H15: ='Base Revenue Driver'!I193 -> -109.41328 | I15: ='Base Revenue Driver'!J193 -> -73.197483 | ... M15: ='Base Revenue Driver'!N193 -> 50.282064
A16: Corporate Expense | B16: ='Base Revenue Driver'!C196 -> 896 | C16: ='Base Revenue Driver'!D196 -> -123.022 | D16: ='Base Revenue Driver'!E196 -> 1769.67 | E16: ='Base Revenue Driver'!F196 -> -189 | F16: ='Base Revenue Driver'!G196 -> -680 | G16: ='Base Revenue Driver'!H196 -> -856 | H16: ='Downside Revenue Driver'!I193 -> -133.45476 | I16: ='Downside Revenue Driver'!J193 -> -102.09289 | J16: ='Downside Revenue Driver'!K193 -> -48.596216 | K16: ='Downside Revenue Driver'!L193 -> 14.162326 | L16: ='Downside Revenue Driver'!M193 -> 21.668359 | M16: ='Downside Revenue Driver'!N193 -> 29.468968
A17: Total EBIT | B17: =SUM(B12:B16) -> -642.893 | C17: =SUM(C12:C16) -> 2278.699 | D17: =SUM(D12:D16) -> 1439.3692 | E17: =SUM(E12:E16) -> 1891.37 | F17: =SUM(F12:F16) -> 1490.844 | G17: =SUM(G12:G16) -> 1001.788 | H17: =SUM(H12:H16) -> 938.6762 | I17: =SUM(I12:I16) -> 1357.9971 | ... M17: =SUM(M12:M16) -> 1841.7688
A18: Adjusted EBIT | B18: ='Base Revenue Driver'!C200 -> -538.893 | C18: ='Base Revenue Driver'!D200 -> 784.699 | D18: ='Base Revenue Driver'!E200 -> 369.36924 | E18: ='Base Revenue Driver'!F200 -> 1492.37 | F18: ='Base Revenue Driver'!G200 -> 1490.844 | G18: ='Base Revenue Driver'!H200 -> 1373.788 | H18: ='Base Revenue Driver'!I200 -> 1315.6436 | I18: ='Base Revenue Driver'!J200 -> 1456.8327 | ... M18: ='Base Revenue Driver'!N200 -> 1912.7614
A20: Interest Expense | B20: 676.38 | C20: 799.593 | D20: 594.954 | E20: 460.293 | F20: 443.23 | G20: 419.042 | H20: =AVERAGE(E20:G20) -> 440.855 | I20: =$H$20 -> 440.855 | J20: =$H$20 -> 440.855 | K20: =$H$20 -> 440.855 | L20: =$H$20 -> 440.855 | M20: =$H$20 -> 440.855
A21: Non-operating items from unconsolidated affiliates | B21: -103.304 | C21: -83.243 | D21: -23.457 | E21: -1.032 | F21: -0.734 | G21: 1.135 | H21: 0 | I21: 0 | J21: 0 | K21: 0 | L21: 0 | M21: 0
A22: Other, net | B22: -89.361 | C22: 65.941 | D22: 82.838 | E22: 42.591 | F22: 70.573 | G22: -303.094 | H22: 0 | I22: 0 | J22: 0 | K22: 0 | L22: 0 | M22: 0
A23: Pre-Tax Income | B23: =B18-B20+B21+B22 -> -1407.938 | C23: =C18-C20+C21+C22 -> -32.196 | D23: =D18-D20+D21+D22 -> -166.20376 | E23: =E18-E20+E21+E22 -> 1073.636 | F23: =F18-F20+F21+F22 -> 1117.453 | G23: =G18-G20+G21+G22 -> 652.787 | H23: =H18-H20+H21+H22 -> 874.78856 | I23: =I18-I20+I21+I22 -> 1015.9777 | ... M23: =M18-M20+M21+M22 -> 1471.9064
A24: Tax Benefit | B24: 191.572 | C24: -253.415 | D24: -697.068 | E24: -157.839 | F24: -52.457 | G24: 240.093 | H24: =0 -> 0 | I24: =H24 -> 0 | J24: =I24 -> 0 | K24: =J24 -> 0 | L24: =K24 -> 0 | M24: =L24 -> 0
A25: Net income attributable to noncontrolling interests | B25: 287.183 | C25: 45.981 | D25: 1266.362 | E25: -172.744 | F25: -318.05 | G25: =-315.01 -> -315.01 | H25: 0 | I25: 0 | J25: 0 | K25: 0 | L25: 0 | M25: 0
A27: Adjusted Net Income | B27: =B23+B24+B25 -> -929.183 | C27: =C23+C24+C25 -> -239.63 | D27: =D23+D24+D25 -> 403.09024 | E27: =E23+E24+E25 -> 743.053 | F27: =F23+F24+F25 -> 746.946 | G27: =G23+G24+G25 -> 577.87 | H27: =H23+H24+H25 -> 874.78856 | I27: =I23+I24+I25 -> 1015.9777 | ... M27: =M23+M24+M25 -> 1471.9064
A29: Depreciation & Amort. | B29: 1210.556 | C29: 1150.61 | D29: 3482.05 | E29: 814.128 | F29: 831.097 | G29: 1017.794 | H29: =+G29*(1+H10) -> 931.89074 | I29: =+H29*(1+I10) -> 939.51532 | J29: =+I29*(1+J10) -> 934.06253 | K29: =+J29*(1+K10) -> 931.30613 | L29: =+K29*(1+L10) -> 926.57041 | M29: =+L29*(1+M10) -> 922.17971
A30: Adjusted EBITDA | B30: =B29+B18 -> 671.663 | C30: =C29+C18 -> 1935.309 | D30: =D29+D18 -> 3851.4192 | E30: =E29+E18 -> 2306.498 | F30: =F29+F18 -> 2321.941 | G30: =G29+G18 -> 2391.582 | H30: =H29+H18 -> 2247.5343 | I30: =I29+I18 -> 2396.348 | ... M30: =M29+M18 -> 2834.9411
A31: EBITDA Margin | B31: =B30/B9 -> 0.14125282 | C31: =C30/C9 -> 0.21234106 | D31: =D30/D9 -> 0.30882386 | E31: =E30/E9 -> 0.1479358 | F31: =F30/F9 -> 0.14048423 | G31: =G30/G9 -> 0.14372986 | H31: =H30/H9 -> 0.14752409 | I31: =I30/I9 -> 0.15601546 | ... M31: =M30/M9 -> 0.18803993
A32: Cash Interest | B32: =B53*B50 -> 816.8655 | C32: =C53*C50 -> 741.56418 | D32: =D53*D50 -> 494.82326 | E32: =E53*E50 -> 445.97262 | F32: =F53*F50 -> 343.55621 | G32: =G53*G50 -> 373.81206 | H32: =H53*H50 -> 293.00692 | I32: =I53*I50 -> 218.0786 | ... M32: =M53*M50 -> 142.87262
A33: Capex | B33: 271 | C33: 491 | D33: 765 | E33: 932 | F33: 1200 | G33: =1100 -> 1100 | H33: =1050 -> 1050 | I33: =$H$33 -> 1050 | J33: =$H$33 -> 1050 | K33: =$H$33 -> 1050 | L33: =$H$33 -> 1050 | M33: =$H$33 -> 1050
A34: Cash Taxes | B34: =B20 -> 676.38 | C34: =C20 -> 799.593 | D34: =D20 -> 594.954 | E34: =E20 -> 460.293 | F34: =F20 -> 443.23 | G34: =G20 -> 419.042 | H34: =H20 -> 440.855 | I34: =I20 -> 440.855 | ... M34: =M20 -> 440.855
A35: FCF | B35: =B30-B32-B33-B34 -> -1092.5825 | C35: =C30-C32-C33-C34 -> -96.84818 | D35: =D30-D32-D33-D34 -> 1996.642 | E35: =E30-E32-E33-E34 -> 468.23238 | F35: =F30-F32-F33-F34 -> 335.15479 | G35: =G30-G32-G33-G34 -> 498.72794 | H35: =H30-H32-H33-H34 -> 463.67239 | I35: =I30-I32-I33-I34 -> 687.4144 | ... M35: =M30-M32-M33-M34 -> 1201.2135
A36: Maintence Capex (60%)
A37: Operating Cash before maturities
A39: Lease Expense | B39: 751.002 | C39: 870.779 | D39: 1986.853 | E39: 2306.64 | F39: 2300.373 | G39: =F39*(1+G10) -> 2315.8633 | H39: =G39*(1+H10) -> 2120.4011 | I39: =H39*(1+I10) -> 2137.7499 | J39: =I39*(1+J10) -> 2125.3428 | K39: =J39*(1+K10) -> 2119.0709 | L39: =K39*(1+L10) -> 2108.2954 | M39: =L39*(1+M10) -> 2098.3049
A41: Credit Matrix
A42: EBIT/Interest | B42: =B18/B20 -> -0.79673113 | C42: =C18/C20 -> 0.98137302 | D42: =D18/D20 -> 0.62083663 | E42: =E18/E20 -> 3.2422175 | F42: =F18/F20 -> 3.36359 | G42: =G18/G20 -> 3.2784017 | H42: =H18/H20 -> 2.9843 | I42: =I18/I20 -> 3.304562 | ... M42: =M18/M20 -> 4.3387539
A43: EBITDA/Interest | B43: =B30/B20 -> 0.99302611 | C43: =C30/C20 -> 2.4203676 | D43: =D30/D20 -> 6.473474 | E43: =E30/E20 -> 5.0109343 | F43: =F30/F20 -> 5.2386819 | G43: =G30/G20 -> 5.7072608 | H43: =H30/H20 -> 5.0981259 | I43: =I30/I20 -> 5.4356829 | ... M43: =M30/M20 -> 6.4305522
A44: (EBITDA - CAPEX)/Interest | B44: =(B30-B33)/B20 -> 0.59236376 | C44: =(C30-C33)/C20 -> 1.8063052 | D44: =(D30-D33)/D20 -> 5.1876603 | E44: =(E30-E33)/E20 -> 2.9861371 | F44: =(F30-F33)/F20 -> 2.531284 | G44: =(G30-G33)/G20 -> 3.0822256 | H44: =(H30-H33)/H20 -> 2.7163904 | I44: =(I30-I33)/I20 -> 3.0539474 | ... M44: =(M30-M33)/M20 -> 4.0488167
A45: Gross Debt/EBITDAR | B45: =B53/(B30+B39) -> 8.6996939 | C45: =C53/(C30+C39) -> 4.194758 | D45: =D53/(D30+D39) -> 1.0866037 | E45: =E53/(E30+E39) -> 1.611241 | F45: =F53/(F30+F39) -> 1.3763998 | G45: =G53/(G30+G39) -> 1.3234782 | H45: =H53/(H30+H39) -> 1.2422468 | I45: =I53/(I30+I39) -> 0.94308748 | ... M45: =M53/(M30+M39) -> 0.4258997
A46: Adjusted Debt/EBITDAR | B46: =B59/(B30+B39) -> 14.597159 | C46: =C59/(C30+C39) -> 8.4007786 | D46: =D59/(D30+D39) -> 5.3942649 | E46: =E59/(E30+E39) -> 7.0581762 | F46: =F59/(F30+F39) -> 6.8014183 | G46: =G59/(G30+G39) -> 6.6262996 | H46: =H59/(H30+H39) -> 6.978469 | I46: =I59/(I30+I39) -> 6.4637982 | ... M46: =M59/(M30+M39) -> 5.4988619
...

Sheet MGM Bond
A1: Owen Purnomo
A2: Paramount
A3: NYSE: MGM
A5: Instrument | B5: Coupon (%) | C5: Maturity | D5: Carrying Value ($mm)
A6: Senior Notes | B6: 4 | C6: 2026 | D6: 750 | F6: MGM Resorts International 6.5% | H6: CUSIP: 552953CJ8 | J6: Ratings: B+/B1/BB-
A7: Senior Notes | B7: 3.7 | C7: 2026 | D7: 400 | F7: Coupon | G7: 0.065 | H7: Today | I7: 46115 | J7: Current Spread & Duration:
A8: Senior Notes | B8: 2.9 | C8: 2027 | D8: 675 | F8: Current Price | G8: 101.37 | H8: Maturity: | I8: 48349 | J8: =(I9-G9)*10000 -> 187.1
A9: Senior Notes | B9: 3.375 | C9: 2027 | D9: 750 | F9: 10 Year T-Yield: | G9: 0.04345 | H9: Current Yield: | I9: 0.06216 | J9: =DURATION(I7,I8,G7,G9,2,0) -> 5.0917935
A10: Senior Notes | B10: 3.7 | C10: 2028 | D10: 750 | F10: Scenario | G10: Spreads | H10: Price | I10: Coupon | J10: 1Y Total Returns
A11: Senior Notes | B11: 4.2 | C11: 2029 | D11: 850 | F11: Upside | G11: 160 | H11: =PRICE($I$7,$I$8,$G$7,($G$9+G11/10000),100,2,0) -> 102.80298 | I11: 6.5 | J11: =(H11-$G$8+I11)/$G$8 -> 0.07825769
A12: Senior Notes | B12: 7.875 | C12: 2031 | D12: 500 | F12: Base | G12: =J8 -> 187.1 | H12: =PRICE($I$7,$I$8,$G$7,($G$9+G12/10000),100,2,0) -> 101.418 | I12: 6.5 | J12: =(H12-$G$8+I12)/$G$8 -> 0.064595014
A13: Senior Notes | B13: 4.95 | C13: 2032 | D13: 750 | F13: Downside | G13: 350 | H13: =PRICE($I$7,$I$8,$G$7,($G$9+G13/10000),100,2,0) -> 93.552273 | I13: 6.5 | J13: =(H13-$G$8+I13)/$G$8 -> -0.012999182
A14: Senior Debentures | B14: 4.2 | C14: 2036 | D14: 0.552 | F14: Downside^2 | G14: 600 | H14: =PRICE($I$7,$I$8,$G$7,($G$9+G14/10000),100,2,0) -> 82.872852 | I14: 6.5 | J14: =(H14-$G$8+I14)/$G$8 -> -0.11835009
B15: 5.5
A16: Due By 2032 | D16: =SUM(D6:D13) -> 5425
A17: Total Debt | D17: =SUM(D6:D14)-30.2 -> 5395.352 | F17: Liquidity Sources | G17: Amount Outstadning | H17: Maturity
F18: Cash | G18: 1500 | H18: -
B19: 5.9 | F19: MGM China Cash | G19: 565 | H19: -
B20: 4.5 | F20: Operating Cash | G20: ='Base MGM IS'!G36 -> 1357.7699 | H20: -
B21: 4.85 | F21: MGM China Revoler | G21: 2512 | H21: -
B22: 4.375 | F22: Revolver (Undrawn) | G22: 2300 | H22: 2028
B23: 4.875 | F23: Yen Credit Facility | G23: 87 | H23: -
B24: 5.85 | F24: Total Liquidity | G24: =G18+G19+G20+G22+G23+G21 -> 8321.7699 | H24: -
B25: 5.25 | F25: Capital Structure
B26: 4.9 | F26: Senior Unsecured | G26: =SUM(D6:D14) -> 5425.552 | H26: 2026 to 2036
B27: 4.6 | F27: Equity | G27: 9440 | H27: -
B28: 4.95 | F28: Total Cushion | G28: =G27 -> 9440 | H28: -
B29: 6.25
B30: 6.375

Sheet Graphs & Tables
A1: Owen Purnomo
B4: MGM | C4: 2020 | D4: 2021 | E4: 2022 | F4: 2023 | G4: 2024 | H4: 2025 | I4: 2026 | J4: 2027 | K4: 2028 | L4: 2029 | M4: 2030 | N4: 2031
B5: Las Vegas Strip Revenue | C5: ='Base MGM IS'!B5 -> 2131.1673 | D5: ='Base MGM IS'!C5 -> 4597.9596 | E5: ='Base MGM IS'!D5 -> 8126.7461 | F5: ='Base MGM IS'!E5 -> 8767.2913 | G5: ='Base MGM IS'!F5 -> 8785.42 | H5: ='Base MGM IS'!G5 -> 8405.3474 | I5: ='Base MGM IS'!H5 -> 8371.5237 | J5: ='Base MGM IS'!I5 -> 8649.8911 | ... N5: ='Base MGM IS'!M5 -> 9786.3801
B6: Regional Operations Revenue | C6: ='Base MGM IS'!B6 -> 1967.171 | D6: ='Base MGM IS'!C6 -> 3305.433 | E6: ='Base MGM IS'!D6 -> 3670.91 | F6: ='Base MGM IS'!E6 -> 3670.309 | G6: ='Base MGM IS'!F6 -> 3720.322 | H6: ='Base MGM IS'!G6 -> 3772.333 | I6: ='Base MGM IS'!H6 -> 3746.8782 | J6: ='Base MGM IS'!I6 -> 3931.1999 | ... N6: ='Base MGM IS'!M6 -> 4424.6001
B7: MGM China Revenue | C7: ='Base MGM IS'!B7 -> 656.703 | D7: ='Base MGM IS'!C7 -> 1210.761 | E7: ='Base MGM IS'!D7 -> 673.593 | F7: ='Base MGM IS'!E7 -> 3153.609 | G7: ='Base MGM IS'!F7 -> 4022.384 | H7: ='Base MGM IS'!G7 -> 4461.743 | I7: ='Base MGM IS'!H7 -> 4268.2451 | J7: ='Base MGM IS'!I7 -> 4705.3844 | ... N7: ='Base MGM IS'!M7 -> 5719.4242
B8: MGM Digital Revenue | C8: ='Base MGM IS'!B8 -> 0 | D8: ='Base MGM IS'!C8 -> 0 | E8: ='Base MGM IS'!D8 -> 0 | F8: ='Base MGM IS'!E8 -> 432.146 | G8: ='Base MGM IS'!F8 -> 552.012 | H8: ='Base MGM IS'!G8 -> 654.19 | I8: ='Base MGM IS'!H8 -> 729.42185 | J8: ='Base MGM IS'!I8 -> 813.30536 | ... N8: ='Base MGM IS'!M8 -> 1257.0516
B9: Total Revenue | C9: =SUM(C5:C8) -> 4755.0413 | D9: =SUM(D5:D8) -> 9114.1536 | E9: =SUM(E5:E8) -> 12471.249 | F9: =SUM(F5:F8) -> 16023.355 | G9: =SUM(G5:G8) -> 17080.138 | H9: =SUM(H5:H8) -> 17293.613 | I9: =SUM(I5:I8) -> 17116.069 | J9: =SUM(J5:J8) -> 18099.781 | ... N9: =SUM(N5:N8) -> 21187.456
B10: Adjusted EBITDA | C10: ='Base MGM IS'!B29 -> 671.663 | D10: ='Base MGM IS'!C29 -> 1935.309 | E10: ='Base MGM IS'!D29 -> 3851.4192 | F10: ='Base MGM IS'!E29 -> 2306.498 | G10: ='Base MGM IS'!F29 -> 2321.941 | H10: ='Base MGM IS'!G29 -> 2391.582 | I10: ='Base MGM IS'!H29 -> 2317.9758 | J10: ='Base MGM IS'!I29 -> 2514.2053 | ... N10: ='Base MGM IS'!M29 -> 3131.8569
B11: Adjusted EBIT | C11: ='Base MGM IS'!B18 -> -538.893 | D11: ='Base MGM IS'!C18 -> 784.699 | E11: ='Base MGM IS'!D18 -> 369.36924 | F11: ='Base MGM IS'!E18 -> 1492.37 | G11: ='Base MGM IS'!F18 -> 1490.844 | H11: ='Base MGM IS'!G18 -> 1373.788 | I11: ='Base MGM IS'!H18 -> 1315.6436 | J11: ='Base MGM IS'!I18 -> 1456.8327 | ... N11: ='Base MGM IS'!M18 -> 1912.7614
B12: Net Income | C12: ='Base MGM IS'!B26 -> -929.183 | D12: ='Base MGM IS'!C26 -> -239.63 | E12: ='Base MGM IS'!D26 -> 403.09024 | F12: ='Base MGM IS'!E26 -> 743.053 | G12: ='Base MGM IS'!F26 -> 746.946 | H12: ='Base MGM IS'!G26 -> 577.87 | I12: ='Base MGM IS'!H26 -> 874.78856 | J12: ='Base MGM IS'!I26 -> 1015.9777 | ... N12: ='Base MGM IS'!M26 -> 1471.9064
B14: Percentage of Revenue | C14: 2020 | D14: 2021 | E14: 2022 | F14: 2023 | G14: 2024 | H14: 2025 | I14: 2026 | J14: 2027 | K14: 2028 | L14: 2029 | M14: 2030 | N14: 2031
B15: Las Vegas Strip | C15: =C5/C9 -> 0.44819112 | D15: =D5/D9 -> 0.50448564 | E15: =E5/E9 -> 0.6516385 | F15: =F5/F9 -> 0.54715702 | G15: =G5/G9 -> 0.5143647 | H15: =H5/H9 -> 0.48603766 | I15: =I5/I9 -> 0.48910318 | J15: =J5/J9 -> 0.47790032 | ... N15: =N5/N9 -> 0.46189501
B16: Regional Operations | C16: =C6/C9 -> 0.41370219 | D16: =D6/D9 -> 0.36267032 | E16: =E6/E9 -> 0.29434983 | F16: =F6/F9 -> 0.22905995 | G16: =G6/G9 -> 0.21781569 | H16: =H6/H9 -> 0.21813446 | I16: =I6/I9 -> 0.21890997 | J16: =J6/J9 -> 0.21719599 | ... N16: =N6/N9 -> 0.20883112
B17: MGM China | C17: =C7/C9 -> 0.13810669 | D17: =D7/D9 -> 0.13284404 | E17: =E7/E9 -> 0.054011671 | F17: =F7/F9 -> 0.19681327 | G17: =G7/G9 -> 0.23550067 | H17: =H7/H9 -> 0.25799946 | I17: =I7/I9 -> 0.24937064 | J17: =J7/J9 -> 0.25996914 | ... N17: =N7/N9 -> 0.26994389
B18: MGM Digital | C18: =C8/C9 -> 0 | D18: =D8/D9 -> 0 | E18: =E8/E9 -> 0 | F18: =F8/F9 -> 0.026969757 | G18: =G8/G9 -> 0.032318943 | H18: =H8/H9 -> 0.037828416 | I18: =I8/I9 -> 0.042616202 | J18: =J8/J9 -> 0.044934542 | ... N18: =N8/N9 -> 0.059329992
B19: EBITDA Margin | C19: =C10/C9 -> 0.14125282 | D19: =D10/D9 -> 0.21234106 | E19: =E10/E9 -> 0.30882386 | F19: =F10/F9 -> 0.14394601 | G19: =G10/G9 -> 0.13594393 | H19: =H10/H9 -> 0.13829279 | I19: =I10/I9 -> 0.13542688 | J19: =J10/J9 -> 0.13890805 | ... N19: =N10/N9 -> 0.14781656
B20: EBIT Margin | C20: =C11/C9 -> -0.11333088 | D20: =D11/D9 -> 0.086096749 | E20: =E11/E9 -> 0.029617662 | F20: =F11/F9 -> 0.093137172 | G20: =G11/G9 -> 0.087285243 | H20: =H11/H9 -> 0.079439037 | I20: =I11/I9 -> 0.076865989 | J20: =J11/J9 -> 0.080488969 | ... N20: =N11/N9 -> 0.09027801
B21: Net Income | C21: =C12/C9 -> -0.19541008 | D21: =D12/D9 -> -0.026292074 | E21: =E12/E9 -> 0.032321561 | F21: =F12/F9 -> 0.046373121 | G21: =G12/G9 -> 0.043731848 | H21: =H12/H9 -> 0.033415226 | I21: =I12/I9 -> 0.051109199 | J21: =J12/J9 -> 0.056132044 | ... N21: =N12/N9 -> 0.069470651
B23: MGM Segement | C23: 2020 | D23: 2021 | E23: 2022 | F23: 2023 | G23: 2024 | H23: 2025 | I23: 2026 | J23: 2027 | K23: 2028 | L23: 2029 | M23: 2030 | N23: 2031
B24: =B15 -> Las Vegas Strip | C24: =C15 -> 0.44819112 | D24: =D15 -> 0.50448564 | E24: =E15 -> 0.6516385 | F24: =F15 -> 0.54715702 | G24: =G15 -> 0.5143647 | H24: =H15 -> 0.48603766 | I24: =I15 -> 0.48910318 | ... N24: =N15 -> 0.46189501
B25: =B16 -> Regional Operations | C25: =C16 -> 0.41370219 | D25: =D16 -> 0.36267032 | E25: =E16 -> 0.29434983 | F25: =F16 -> 0.22905995 | G25: =G16 -> 0.21781569 | H25: =H16 -> 0.21813446 | I25: =I16 -> 0.21890997 | ... N25: =N16 -> 0.20883112
B26: =B17 -> MGM China | C26: =C17 -> 0.13810669 | D26: =D17 -> 0.13284404 | E26: =E17 -> 0.054011671 | F26: =F17 -> 0.19681327 | G26: =G17 -> 0.23550067 | H26: =H17 -> 0.25799946 | I26: =I17 -> 0.24937064 | ... N26: =N17 -> 0.26994389
B27: MGM Digital | C27: =C18 -> 0 | D27: =D18 -> 0 | E27: =E18 -> 0 | F27: =F18 -> 0.026969757 | G27: =G18 -> 0.032318943 | H27: =H18 -> 0.037828416 | I27: =I18 -> 0.042616202 | J27: =J18 -> 0.044934542 | ... N27: =N18 -> 0.059329992
B29: Margins | C29: 2020 | D29: 2021 | E29: 2022 | F29: 2023 | G29: 2024 | H29: 2025 | I29: 2026 | J29: 2027 | K29: 2028 | L29: 2029 | M29: 2030 | N29: 2031
B30: {=B19:B21} -> EBITDA Margin | C30: =C19 -> 0.14125282 | D30: =D19 -> 0.21234106 | E30: =E19 -> 0.30882386 | F30: =F19 -> 0.14394601 | G30: =G19 -> 0.13594393 | H30: =H19 -> 0.13829279 | I30: =I19 -> 0.13542688 | J30: =J19 -> 0.13890805 | ... N30: =N19 -> 0.14781656
B31: EBIT Margin | C31: =C20 -> -0.11333088 | D31: =D20 -> 0.086096749 | E31: =E20 -> 0.029617662 | F31: =F20 -> 0.093137172 | G31: =G20 -> 0.087285243 | H31: =H20 -> 0.079439037 | I31: =I20 -> 0.076865989 | J31: =J20 -> 0.080488969 | ... N31: =N20 -> 0.09027801
B32: Net Income | C32: =C21 -> -0.19541008 | D32: =D21 -> -0.026292074 | E32: =E21 -> 0.032321561 | F32: =F21 -> 0.046373121 | G32: =G21 -> 0.043731848 | H32: =H21 -> 0.033415226 | I32: =I21 -> 0.051109199 | J32: =J21 -> 0.056132044 | ... N32: =N21 -> 0.069470651
B34: Credit Metrics | C34: 2020 | D34: 2021 | E34: 2022 | F34: 2023 | G34: 2024 | H34: 2025 | I34: 2026 | J34: 2027 | K34: 2028 | L34: 2029 | M34: 2030 | N34: 2031
B35: {='Base MGM IS'!A41:A46} -> EBIT/Interest | C35: ='Base MGM IS'!B41 -> -0.79673113 | D35: ='Base MGM IS'!C41 -> 0.98137302 | E35: ='Base MGM IS'!D41 -> 0.62083663 | F35: ='Base MGM IS'!E41 -> 3.2422175 | G35: ='Base MGM IS'!F41 -> 3.36359 | H35: ='Base MGM IS'!G41 -> 3.2784017 | I35: ='Base MGM IS'!H41 -> 2.9843 | J35: ='Base MGM IS'!I41 -> 3.304562 | ... N35: ='Base MGM IS'!M41 -> 4.3387539
B36: EBITDA/Interest | C36: ='Base MGM IS'!B42 -> 0.99302611 | D36: ='Base MGM IS'!C42 -> 2.4203676 | E36: ='Base MGM IS'!D42 -> 6.473474 | F36: ='Base MGM IS'!E42 -> 5.0109343 | G36: ='Base MGM IS'!F42 -> 5.2386819 | H36: ='Base MGM IS'!G42 -> 5.7072608 | I36: ='Base MGM IS'!H42 -> 5.2579098 | J36: ='Base MGM IS'!I42 -> 5.703021 | ... N36: ='Base MGM IS'!M42 -> 7.104052
B37: (EBITDA - CAPEX)/Interest | C37: ='Base MGM IS'!B43 -> 0.59236376 | D37: ='Base MGM IS'!C43 -> 1.8063052 | E37: ='Base MGM IS'!D43 -> 5.1876603 | F37: ='Base MGM IS'!E43 -> 2.9861371 | G37: ='Base MGM IS'!F43 -> 2.531284 | H37: ='Base MGM IS'!G43 -> 3.0822256 | I37: ='Base MGM IS'!H43 -> 2.8761743 | J37: ='Base MGM IS'!I43 -> 3.3212855 | ... N37: ='Base MGM IS'!M43 -> 4.7223165
B38: Gross Debt/EBITDAR | C38: ='Base MGM IS'!B44 -> 8.6996939 | D38: ='Base MGM IS'!C44 -> 4.551126 | E38: ='Base MGM IS'!D44 -> 1.3068743 | F38: ='Base MGM IS'!E44 -> 1.611241 | G38: ='Base MGM IS'!F44 -> 1.3763998 | H38: ='Base MGM IS'!G44 -> 1.3234782 | I38: ='Base MGM IS'!H44 -> 1.1799212 | J38: ='Base MGM IS'!I44 -> 0.869094 | ... N38: ='Base MGM IS'!M44 -> 0.3557661
B39: Adjusted Debt/EBITDAR | C39: ='Base MGM IS'!B45 -> 14.597159 | D39: ='Base MGM IS'!C45 -> 8.7571466 | E39: ='Base MGM IS'!D45 -> 5.6145355 | F39: ='Base MGM IS'!E45 -> 7.0581762 | G39: ='Base MGM IS'!F45 -> 6.8014183 | H39: ='Base MGM IS'!G45 -> 6.6262996 | I39: ='Base MGM IS'!H45 -> 6.6283474 | J39: ='Base MGM IS'!I45 -> 5.9566566 | ... N39: ='Base MGM IS'!M45 -> 4.5933554
B40: FCF/ Debt | C40: ='Base MGM IS'!B46 -> -0.052611812 | D40: ='Base MGM IS'!C46 -> -0.0065049474 | E40: ='Base MGM IS'!D46 -> 0.05785177 | F40: ='Base MGM IS'!E46 -> 0.014380451 | G40: ='Base MGM IS'!F46 -> 0.010660719 | H40: ='Base MGM IS'!G46 -> 0.015988486 | I40: ='Base MGM IS'!H46 -> 0.017522559 | J40: ='Base MGM IS'!I46 -> 0.027476648 | ... N40: ='Base MGM IS'!M46 -> 0.055226013
