Workbook

Sheet 0000000

Sheet Revenue Driver
A1: Owen Purnomo
A2: Paramount
A3: NASDAQ: PSKY
A4: Segment Revenue Driver
A5: Segment | B5: Metrics | C5: 2022 | D5: 2023 | E5: 2024 | F5: 2025 | G5: 2026 | H5: 2027 | I5: 2028 | J5: 2029
A6: TV Media
A7: Advertising | B7: Audience Change % | C7: -0.0947 | D7: -0.1443 | E7: -0.121 | F7: -0.1789 | G7: =-13% -> -0.13 | H7: =G7 -> -0.13 | I7: =G7 -> -0.13 | J7: =H7 -> -0.13
B8: CPM Pricing Growth % | C8: 0.02 | D8: 0.02 | E8: 0.02 | F8: 0.02 | G8: 0.02 | H8: =G8 -> 0.02 | I8: =G8 -> 0.02 | J8: =H8 -> 0.02 | L8: https://adsmanager.paramount.com/insights/ctv-advertising-cost#CTV-ADVERTISING-BEST-PRACTICES-TO-OPTIMIZE-CPMS
B9: Political Adjustment % | C9: 0 | D9: 0 | E9: 0.03 | F9: 0 | G9: 0.01 | H9: 0 | I9: 0.03 | J9: 0 | L9: https://clients-mintel-com.ezproxy.bu.edu/report/television-advertising-incl-impact-of-covid-19-us-august-2020?fromSearch=%3Ffilters.category%3D120%26filters.region%3D14%26freetext%3DTV%26resultPosition%3D13
B10: Event (Sports) Adjustment % | C10: 0 | D10: 0 | E10: 0.07 | F10: 0 | G10: 0 | H10: 0 | I10: 0 | J10: 0 | L10: https://www.mediadynamicsinc.com/uploads/files/UPFRONT-2024-25-PRESS-RELEASE-FINAL-MZ4.pdf
B11: Revenue Growth % | C11: =SUM(C7:C10) -> -0.0747 | D11: =SUM(D7:D10) -> -0.1243 | E11: =SUM(E7:E10) -> -0.001 | F11: =SUM(F7:F10) -> -0.1589 | G11: =SUM(G7:G10) -> -0.1 | H11: =SUM(H7:H10) -> -0.11 | I11: =SUM(I7:I10) -> -0.08 | J11: =SUM(J7:J10) -> -0.11
B12: Advirtising Revenue (USD mm) | C12: =10105*(1+C11) -> 9350.1565 | D12: =C12*(D11+1) -> 8187.932 | E12: =D12*(E11+1) -> 8179.7441 | F12: =E12*(F11+1) -> 6879.9828 | G12: =F12*(G11+1) -> 6191.9845 | H12: =G12*(H11+1) -> 5510.8662 | I12: =H12*(I11+1) -> 5069.9969 | J12: =I12*(J11+1) -> 4512.2972
A13: Affiliate
B14: Subscribers (mm) | C14: 75.82499 | D14: 74.94438 | E14: 70.88432 | F14: 67.34334 | G14: =F14*(G15+1) -> 63.976173 | H14: =G14*(H15+1) -> 60.777364 | I14: =H14*(I15+1) -> 57.738496 | J14: =I14*(J15+1) -> 54.851571
B15: Subscriber Growth % | C15: =(C14/56)-1 -> 0.35401768 | D15: =(D14/75.82499)-1 -> -0.011613717 | E15: =(E14/D14)-1 -> -0.054174309 | F15: =(F14/E14)-1 -> -0.049954348 | G15: -0.05 | H15: =G15 -> -0.05 | I15: =H15 -> -0.05 | J15: =I15 -> -0.05
B16: Affiliate Fee ($ per month) | C16: 8.99 | D16: 8.99 | E16: 8.99 | F16: 8.99 | G16: 8.99 | H16: =$G$16 -> 8.99 | I16: =$G$16 -> 8.99 | J16: =$G$16 -> 8.99
B17: Affiliate Fee ($ per year) | C17: =C16*12 -> 107.88 | D17: =D16*12 -> 107.88 | E17: =E16*12 -> 107.88 | F17: =F16*12 -> 107.88 | G17: =G16*12 -> 107.88 | H17: =H16*12 -> 107.88 | I17: =I16*12 -> 107.88 | J17: =J16*12 -> 107.88
B18: Fee Growth % | C18: 0 | D18: =(D17/C17)-1 -> 0 | E18: =(E17/D17)-1 -> 0 | F18: =(F17/E17)-1 -> 0 | G18: =(G17/F17)-1 -> 0 | H18: =(H17/G17)-1 -> 0 | I18: =(I17/H17)-1 -> 0 | J18: =(J17/I17)-1 -> 0
B19: Revenue Growth % | C19: =(C20/8413)-1 -> -0.027695243 | D19: =(D20/8180)-1 -> -0.011613727 | E19: =(E20/D20)-1 -> -0.054174309 | F19: =(F20/E20)-1 -> -0.049954348 | G19: =(G20/F20)-1 -> -0.05 | H19: =(H20/G20)-1 -> -0.05 | I19: =(I20/H20)-1 -> -0.05 | J19: =(J20/I20)-1 -> -0.05
B20: Affiliate Revenue | C20: =C14*C17 -> 8179.9999 | D20: =D14*D17 -> 8084.9997 | E20: =E14*E17 -> 7647.0004 | F20: =F14*F17 -> 7264.9995 | G20: =G14*G17 -> 6901.7495 | H20: =H14*H17 -> 6556.6621 | I20: =I14*I17 -> 6228.829 | J20: =J14*J17 -> 5917.3875
A21: Licensing & Other
B22: Revenue Growth % | C22: =(C23/4126)-1 -> 0.018419777 | D22: =(D23/4202)-1 -> -0.092812946 | E22: =(E23/D23)-1 -> -0.22560336 | F22: =(F23/E23)-1 -> 0.51355014 | G22: 0.02 | H22: =G22 -> 0.02 | I22: =H22 -> 0.02 | J22: =I22 -> 0.02
B23: Licensing & Other Revenue (USD mm) | C23: 4202 | D23: 3812 | E23: 2952 | F23: =(3351/9)*12 -> 4468 | G23: =F23*(G22+1) -> 4557.36 | H23: =G23*(H22+1) -> 4648.5072 | I23: =H23*(I22+1) -> 4741.4773 | J23: =I23*(J22+1) -> 4836.3069
B25: Segment Revenue (USD mm) | C25: =C12+C20+C23 -> 21732.156 | D25: =D12+D20+D23 -> 20084.932 | E25: =E12+E20+E23 -> 18778.745 | F25: =F12+F20+F23 -> 18612.982 | G25: =G12+G20+G23 -> 17651.094 | H25: =H12+H20+H23 -> 16716.035 | I25: =I12+I20+I23 -> 16040.303 | J25: =J12+J20+J23 -> 15265.992
B26: Segment of Total Revenue % | C26: =C25/C62 -> 0.73198969 | D26: =D25/D62 -> 0.67449049 | E26: =E25/E62 -> 0.63926021 | F26: =F25/F62 -> 0.62027459 | G26: =G25/G62 -> 0.58861158 | H26: =H25/H62 -> 0.59299914 | I26: =I25/I62 -> 0.58379543 | J26: =J25/J62 -> 0.56871967
B27: Segement OIBDA | C27: 5451 | D27: 4791 | E27: 4348 | F27: 3350
B28: EBIT Margin % | C28: =C29/C25 -> 0.23718512 | D28: =D29/D25 -> 0.22449979 | E28: =E29/E25 -> 0.21819403 | F28: 0.2 | G28: 0.2 | H28: =G28 -> 0.2 | I28: =G28 -> 0.2 | J28: =H28 -> 0.2
B29: EBIT (USD mm) | C29: =C27-(405*C26) -> 5154.5442 | D29: =D27-(418*D26) -> 4509.063 | E29: =E27-(E26*392) -> 4097.41 | F29: =F25*F28 -> 3722.5965 | G29: =G25*G28 -> 3530.2188 | H29: =H25*H28 -> 3343.2071 | I29: =I25*I28 -> 3208.0606 | J29: =J25*J28 -> 3053.1983
A31: Direct to Consumer
B32: Paramount+ Subscribers (mm) | C32: 56 | D32: 67.5 | E32: 77.5 | F32: =(79.1/12)*12 -> 79.1 | G32: =+F32*(1+G33) -> 80.682 | H32: =+G32*(1+H33) -> 82.29564 | I32: =+H32*(1+I33) -> 83.941553 | J32: =+I32*(1+J33) -> 85.620384
B33: Net adds% | C33: =(C32/43)-1 -> 0.30232558 | D33: =(D32/56)-1 -> 0.20535714 | E33: =(E32/D32)-1 -> 0.14814815 | F33: =(F32/E32)-1 -> 0.020645161 | G33: 0.02 | H33: =+$G$33 -> 0.02 | I33: =+$G$33 -> 0.02 | J33: =+$G$33 -> 0.02
B34: ARPU ($/year) | C34: =C37/C32 -> 60.196429 | D34: =D37/D32 -> 73.081481 | E34: =E37/E32 -> 71.045161 | F34: =F37/F32 -> 82.983565 | G34: =+F34*(1+G35) -> 82.983565 | H34: =+G34*(1+H35) -> 82.983565 | I34: =+H34*(1+I35) -> 82.983565 | J34: =+I34*(1+J35) -> 82.983565
B35: ARPU Growth % | C35: =(C34/(4.6*12)-1) -> 0.09051501 | D35: =(D34/60.2)-1 -> 0.2139781 | E35: =(E34/D34)-1 -> -0.027863696 | F35: =(F34/E34)-1 -> 0.16803965 | G35: 0 | H35: =$G$35 -> 0 | I35: =$G$35 -> 0 | J35: =$G$35 -> 0
B36: Advertising Revenue | C36: 1533 | D36: 1795 | E36: 2114 | F36: =(1446/9)*12 -> 1928 | G36: =F36*(1+G33) -> 1966.56 | H36: =G36*(1+H33) -> 2005.8912 | I36: =H36*(1+I33) -> 2046.009 | J36: =I36*(1+J33) -> 2086.9292
B37: Subscription Revenue | C37: 3371 | D37: 4933 | E37: 5506 | F37: =(4923/9)*12 -> 6564 | G37: =G32*G34 -> 6695.28 | H37: =H32*H34 -> 6829.1856 | I37: =I32*I34 -> 6965.7693 | J37: =J32*J34 -> 7105.0847
B38: Licensing Revenue | C38: 0 | D38: 8 | E38: 12 | F38: =(2/9)*12 -> 2.6666667 | G38: =F38*(1+G33) -> 2.72 | H38: =G38*(1+H33) -> 2.7744 | I38: =H38*(1+I33) -> 2.829888 | J38: =I38*(1+J33) -> 2.8864858
B39: Segment Revenue (USD mm) | C39: =SUM(C36:C38) -> 4904 | D39: =SUM(D36:D38) -> 6736 | E39: =SUM(E36:E38) -> 7632 | F39: =SUM(F36:F38) -> 8494.6667 | G39: =SUM(G36:G38) -> 8664.56 | H39: =SUM(H36:H38) -> 8837.8512 | I39: =SUM(I36:I38) -> 9014.6082 | J39: =SUM(J36:J38) -> 9194.9004
B40: Segment of Total Revenue % | C40: =C39/C62 -> 0.16517815 | D40: =D39/D62 -> 0.22620779 | E40: =E39/E62 -> 0.25980618 | F40: =F39/F62 -> 0.28308338 | G40: =G39/G62 -> 0.28893735 | H40: =H39/H62 -> 0.3135216 | I40: =I39/I62 -> 0.3280915 | J40: =J39/J62 -> 0.34254707
B41: Segement OIBDA | C41: -1819 | D41: -1663 | E41: -497 | F41: =((235/9)*12) -> 313.33333
B42: EBIT Margin % | C42: =C43/C39 -> -0.38456304 | D42: =D43/D39 -> -0.26091966 | E42: =E43/E39 -> -0.078464888 | F42: =F43/F39 -> 0.026844005 | G42: =2.5% -> 0.025 | H42: =G42 -> 0.025 | I42: =G42 -> 0.025 | J42: =H42 -> 0.025
...

Sheet PSKY IS
A1: Owen Purnomo
A2: Paramount
A3: NASDAQ: PSKY
A4: Income Statement | B4: 2022 | C4: 2023 | D4: 2024 | E4: 2025 | F4: 2026 | G4: 2027 | H4: 2028 | I4: 2029
A5: TV Media Revenue | B5: ='Revenue Driver'!C25 -> 21732.156 | C5: ='Revenue Driver'!D25 -> 20084.932 | D5: ='Revenue Driver'!E25 -> 18778.745 | E5: ='Revenue Driver'!F25 -> 18612.982 | F5: ='Revenue Driver'!G25 -> 17651.094 | G5: ='Revenue Driver'!H25 -> 16716.035 | H5: ='Revenue Driver'!I25 -> 16040.303 | I5: ='Revenue Driver'!J25 -> 15265.992
A6: Direct to Consumer Revenue | B6: ='Revenue Driver'!C39 -> 4904 | C6: ='Revenue Driver'!D39 -> 6736 | D6: ='Revenue Driver'!E39 -> 7632 | E6: ='Revenue Driver'!F39 -> 8494.6667 | F6: ='Revenue Driver'!G39 -> 8664.56 | G6: ='Revenue Driver'!H39 -> 8837.8512 | H6: ='Revenue Driver'!I39 -> 9014.6082 | I6: ='Revenue Driver'!J39 -> 9194.9004
A7: Filmed Entertainment Revenue | B7: ='Revenue Driver'!C53 -> 3053 | C7: ='Revenue Driver'!D53 -> 2957 | D7: ='Revenue Driver'!E53 -> 2965 | E7: ='Revenue Driver'!F53 -> 2900 | F7: ='Revenue Driver'!G53 -> 3672.023 | G7: ='Revenue Driver'!H53 -> 2635.0844 | H7: ='Revenue Driver'!I53 -> 2420.9856 | I7: ='Revenue Driver'!J53 -> 2381.8434
A8: Total Revenue | B8: =SUM(B5:B7) -> 29689.156 | C8: =SUM(C5:C7) -> 29777.932 | D8: =SUM(D5:D7) -> 29375.745 | E8: =SUM(E5:E7) -> 30007.649 | F8: =SUM(F5:F7) -> 29987.677 | G8: =SUM(G5:G7) -> 28188.971 | H8: =SUM(H5:H7) -> 27475.897 | I8: =SUM(I5:I7) -> 26842.735
A9: Grotwh Rate | B9: =(B8/28590)-1 -> 0.038445485 | C9: =(C8/B8)-1 -> 0.0029901604 | D9: =(D8/C8)-1 -> -0.013506217 | E9: =(E8/D8)-1 -> 0.021511094 | F9: =(F8/E8)-1 -> -0.00066556036 | G9: =(G8/F8)-1 -> -0.059981506 | H9: =(H8/G8)-1 -> -0.025296205 | I9: =(I8/H8)-1 -> -0.023044254
A11: TV Media EBIT | B11: ='Revenue Driver'!C29 -> 5154.5442 | C11: ='Revenue Driver'!D29 -> 4509.063 | D11: ='Revenue Driver'!E29 -> 4097.41 | E11: ='Revenue Driver'!F29 -> 3722.5965 | F11: ='Revenue Driver'!G29 -> 3530.2188 | G11: ='Revenue Driver'!H29 -> 3343.2071 | H11: ='Revenue Driver'!I29 -> 3208.0606 | I11: ='Revenue Driver'!J29 -> 3053.1983
A12: Direct to Consumer EBIT | B12: ='Revenue Driver'!C43 -> -1885.8972 | C12: ='Revenue Driver'!D43 -> -1757.5549 | D12: ='Revenue Driver'!E43 -> -598.84402 | E12: ='Revenue Driver'!F43 -> 228.03088 | F12: ='Revenue Driver'!G43 -> 216.614 | G12: ='Revenue Driver'!H43 -> 220.94628 | H12: ='Revenue Driver'!I43 -> 225.36521 | I12: ='Revenue Driver'!J43 -> 229.87251
A13: Filmed Entertainment EBIT | B13: ='Revenue Driver'!C57 -> 230.35298 | C13: ='Revenue Driver'!D57 -> -160.50812 | D13: ='Revenue Driver'!E57 -> -158.56598 | E13: ='Revenue Driver'!F57 -> -42.121464 | F13: ='Revenue Driver'!G57 -> 73.44046 | G13: ='Revenue Driver'!H57 -> 52.701687 | H13: ='Revenue Driver'!I57 -> 48.419712 | I13: ='Revenue Driver'!J57 -> 47.636869
A14: Corporate Expense | B14: ='Revenue Driver'!C59 -> -1157 | C14: ='Revenue Driver'!D59 -> -3042 | D14: ='Revenue Driver'!E59 -> -8609 | E14: ='Revenue Driver'!F59 -> -2211.2 | F14: ='Revenue Driver'!G59 -> -2800 | G14: ='Revenue Driver'!H59 -> -2800 | H14: ='Revenue Driver'!I59 -> -2800 | I14: ='Revenue Driver'!J59 -> -2800
A15: Total EBIT (Operating Income) | B15: =SUM(B9:B14) -> 2342.0384 | C15: =SUM(C9:C14) -> -450.99701 | D15: =SUM(D9:D14) -> -5269.0135 | E15: =SUM(E9:E14) -> 1697.3274 | F15: =SUM(F9:F14) -> 1020.2726 | G15: =SUM(G9:G14) -> 816.79508 | H15: =SUM(H9:H14) -> 681.82026 | I15: =SUM(I9:I14) -> 530.68466
A16: Adjusted EBIT | B16: ='Revenue Driver'!C64 -> 2342 | C16: ='Revenue Driver'!D64 -> -368 | D16: ='Revenue Driver'!E64 -> 1769 | E16: ='Revenue Driver'!F64 -> 1697.3059 | F16: ='Revenue Driver'!G64 -> 1020.2733 | G16: ='Revenue Driver'!H64 -> 816.85506 | H16: ='Revenue Driver'!I64 -> 681.84556 | I16: ='Revenue Driver'!J64 -> 530.70771
A18: Interest Income | B18: 108 | C18: 137 | D18: 151 | E18: =AVERAGE(B18:D18) -> 132 | F18: =E18 -> 132 | G18: =F18 -> 132 | H18: =G18 -> 132 | I18: =H18 -> 132
A19: Interest Expense | B19: 931 | C19: 920 | D19: 860 | E19: =AVERAGE(B19:D19) -> 903.66667 | F19: =$E$19 -> 903.66667 | G19: =$E$19 -> 903.66667 | H19: =$E$19 -> 903.66667 | I19: =$E$19 -> 903.66667
A20: Pre-Tax Income | B20: =B16+B18-B19+(-9-120-124) -> 1266 | C20: =C16+C18-C19+(168+29-216) -> -1170 | D20: =D16+D18-D19+(-17-182) -> 861 | E20: =E16+E18-E19 -> 925.6392 | F20: =F16+F18-F19 -> 248.6066 | G20: =G16+G18-G19 -> 45.188395 | H20: =H16+H18-H19 -> -89.821106 | I20: =I16+I18-I19 -> -240.95896
A21: Tax Benefit | B21: -227 | C21: 361 | D21: 305 | E21: =AVERAGE(B21:D21) -> 146.33333 | F21: =AVERAGE(B21:E21) -> 146.33333 | G21: =AVERAGE(B21:F21) -> 146.33333 | H21: =AVERAGE(B21:G21) -> 146.33333 | I21: =AVERAGE(B21:H21) -> 146.33333
A22: Equity in loss of investee companies, net of tax | B22: -204 | C22: -360 | D22: -291 | E22: =AVERAGE(B22:D22) -> -285 | F22: =AVERAGE(B22:E22) -> -285 | G22: =AVERAGE(B22:F22) -> -285 | H22: =AVERAGE(B22:G22) -> -285 | I22: =AVERAGE(B22:H22) -> -285
A23: Earnings from discontinued operations, net of tax | B23: 379 | C23: 676 | D23: 14 | E23: 0 | F23: 0 | G23: 0 | H23: 0 | I23: 0
A24: Net earnings attributable to noncontrolling interests | B24: -110 | C24: -32 | D24: -41 | E24: 0 | F24: 0 | G24: 0 | H24: 0 | I24: 0
A25: Net Income | B25: =B20+B21+B22+B23+B24 -> 1104 | C25: =C20+C21+C22+C23+C24 -> -525 | D25: =D20+D21+D22+D23+D24 -> 848 | E25: =E20+E21+E22+E23+E24 -> 786.97254 | F25: =F20+F21+F22+F23+F24 -> 109.93994 | G25: =G20+G21+G22+G23+G24 -> -93.478272 | H25: =H20+H21+H22+H23+H24 -> -228.48777 | I25: =I20+I21+I22+I23+I24 -> -379.62562
A27: Depreciation & Amort. | B27: 405 | C27: 418 | D27: 392 | E27: =+D27*(1+E9) -> 400.43235 | F27: =+E27*(1+F9) -> 400.16584 | G27: =+F27*(1+G9) -> 376.16329 | H27: =+G27*(1+H9) -> 366.64778 | I27: =+H27*(1+I9) -> 358.19866
A28: Adjusted EBITDA | B28: =B27+B16 -> 2747 | C28: =C27+C16 -> 50 | D28: =D27+D16 -> 2161 | E28: =E27+E16 -> 2097.7382 | F28: =F27+F16 -> 1420.4391 | G28: =G27+G16 -> 1193.0183 | H28: =H27+H16 -> 1048.4933 | I28: =I27+I16 -> 888.90637
A29: EBITDA Margin | B29: =B28/B8 -> 0.092525364 | C29: =C28/C8 -> 0.0016790958 | D29: =D28/D8 -> 0.073564093 | E29: =E28/E8 -> 0.069906783 | F29: =F28/F8 -> 0.047367427 | G29: =G28/G8 -> 0.042322167 | H29: =H28/H8 -> 0.038160477 | I29: =I28/I8 -> 0.033115342
A30: Cash Interest | B30: =B49*B46 -> 904.80437 | C30: =C49*C46 -> 833.14817 | D30: =D49*D46 -> 818.56877 | E30: =E49*E46 -> 836.50867 | F30: =F49*F46 -> 814.12257 | G30: =G49*G46 -> 783.92977 | H30: =H49*H46 -> 732.22977 | I30: =I49*I46 -> 706.37977
A31: Capex | B31: 358 | C31: 328 | D31: 263 | E31: =((46+134)/9)*12 -> 240 | F31: =$E$31 -> 240 | G31: =$E$31 -> 240 | H31: =$E$31 -> 240 | I31: =E31 -> 240
A32: Cash Taxes | B32: =B19 -> 931 | C32: =C19 -> 920 | D32: =D19 -> 860 | E32: =E19 -> 903.66667 | F32: =F19 -> 903.66667 | G32: =G19 -> 903.66667 | H32: =H19 -> 903.66667 | I32: =I19 -> 903.66667
A33: FCF | B33: =B28-B30-B31-B32 -> 553.19563 | C33: =C28-C30-C31-C32 -> -2031.1482 | D33: =D28-D30-D31-D32 -> 219.43123 | E33: =E28-E30-E31-E32 -> 117.56288 | F33: =F28-F30-F31-F32 -> -537.35013 | G33: =G28-G30-G31-G32 -> -734.57809 | H33: =H28-H30-H31-H32 -> -827.4031 | I33: =I28-I30-I31-I32 -> -961.14007
A35: Lease Expense | B35: 744 | C35: 630 | D35: 559 | E35: 333 | F35: 265 | G35: 215 | H35: 196 | I35: 152
A37: Credit Matrix | K37: Paramount’s credit profile is weaker than its current Ba1/BB+ rating implies, with leverage and coverage metrics deteriorating toward low-B and potentially CCC+ territory by 2029 absent structural improvement in operating performance.
A38: EBIT/Interest | B38: =B16/B19 -> 2.5155747 | C38: =C16/C19 -> -0.4 | D38: =D16/D19 -> 2.0569767 | E38: =E16/E19 -> 1.8782433 | F38: =F16/F19 -> 1.1290372 | G38: =G16/G19 -> 0.90393404 | H38: =H16/H19 -> 0.75453216 | I38: =I16/I19 -> 0.5872826
A39: EBITDA/Interest | B39: =B28/B19 -> 2.9505908 | C39: =C28/C19 -> 0.054347826 | D39: =D28/D19 -> 2.5127907 | E39: =E28/E19 -> 2.3213628 | F39: =F28/F19 -> 1.5718618 | G39: =G28/G19 -> 1.3201974 | H39: =H28/H19 -> 1.1602656 | I39: =I28/I19 -> 0.98366621
A40: (EBITDA - CAPEX)/Interest | B40: =(B28-B31)/B19 -> 2.566058 | C40: =(C28-C31)/C19 -> -0.30217391 | D40: =(D28-D31)/D19 -> 2.2069767 | E40: =(E28-E31)/E19 -> 2.0557782 | F40: =(F28-F31)/F19 -> 1.3062771 | G40: =(G28-G31)/G19 -> 1.0546127 | H40: =(H28-H31)/H19 -> 0.89468094 | I40: =(I28-I31)/I19 -> 0.71808156
A41: Gross Debt/EBITDAR | D41: =D49/(D28+D35) -> 5.8209749 | E41: =E49/(E28+E35) -> 6.6564353 | F41: =F49/(F28+F35) -> 9.3429965 | G41: =G49/(G28+G35) -> 10.769073 | H41: =H49/(H28+H35) -> 11.380576 | I41: =I49/(I28+I35) -> 13.12611
A42: NET Debt/EBITDAR | D42: =D55/(D28+D35) -> 6.8136219 | E42: =E55/(E28+E35) -> 7.767209 | F42: =F55/(F28+F35) -> 10.944953 | G42: =G55/(G28+G35) -> 12.686661 | H42: =H55/(H28+H35) -> 13.550134 | I42: =I55/(I28+I35) -> 15.720003
A43: FCF/ Debt | D43: =D33/D55 -> 0.011839994 | E43: =E33/E55 -> 0.0062268304 | F43: =F33/F55 -> -0.029129323 | G43: =G33/G55 -> -0.041122766 | H43: =H33/H55 -> -0.049066036 | I43: =I33/I55 -> -0.058738436
A45: Note 8 & 9: Debt & Leases
A46: Interest Rate | B46: 0.0517 | C46: 0.0517 | D46: 0.0517 | E46: 0.0517 | F46: 0.0517 | G46: 0.0517 | H46: 0.0517 | I46: 0.0517
...

Sheet PSKY Bond
A1: Owen Purnomo
A2: Paramount
A3: NASDAQ: PSKY
A5: Instrument | B5: Coupon (%) | C5: Maturity | D5: Carrying Value ($mm) | E5: Category
A6: Senior Notes | B6: 4 | C6: 2026 | D6: 346 | E6: Senior | H6: Paramoung Global 4.95% Due 2031 | J6: CUSIP: 92556HAB3 | L6: Ratings: Baa3/BB+/BBB-
A7: Senior Notes | B7: 3.7 | C7: 2026 | D7: 86 | E7: Senior | H7: Coupon | I7: 0.0495 | J7: Today | K7: 46073 | L7: Current Spread & Duration:
A8: Senior Notes | B8: 2.9 | C8: 2027 | D8: 582 | E8: Senior | H8: Current Price | I8: 95.85 | J8: Maturity: | K8: 47863 | L8: =(K9-I9)*10000 -> 184.6
A9: Senior Notes | B9: 3.375 | C9: 2028 | D9: 498 | E9: Senior | H9: 10 Year T-Yield: | I9: 0.04087 | J9: Current Yield: | K9: 0.05933 | L9: =DURATION(K7,K8,I7,I9,2,0) -> 4.4044706
A10: Senior Notes | B10: 3.7 | C10: 2028 | D10: 496 | E10: Senior | H10: Scenario | I10: Spreads | J10: Price | K10: Coupon | L10: 1Y Total Returns
A11: Senior Notes | B11: 4.2 | C11: 2029 | D11: 496 | E11: Senior | H11: Upside | I11: 150 | J11: =PRICE($K$7,$K$8,$I$7,($I$9+I11/10000),100,2,0) -> 97.295443 | K11: 4.95 | L11: =(J11-$I$8+K11)/$I$8 -> 0.066723456
A12: Senior Debentures | B12: 7.875 | C12: 2030 | D12: 829 | E12: Senior | H12: Base | I12: =L8 -> 184.6 | J12: =PRICE($K$7,$K$8,$I$7,($I$9+I12/10000),100,2,0) -> 95.865086 | K12: 4.95 | L12: =(J12-$I$8+K12)/$I$8 -> 0.05180058
A13: Senior Notes | B13: 4.95 | C13: 2031 | D13: 1232 | E13: Senior | H13: Downside | I13: 350 | J13: =PRICE($K$7,$K$8,$I$7,($I$9+I13/10000),100,2,0) -> 89.361842 | K13: 4.95 | L13: =(J13-$I$8+K13)/$I$8 -> -0.016047551
A14: Senior Notes | B14: 4.2 | C14: 2032 | D14: 980 | E14: Senior | H14: Downside^2 | I14: 700 | J14: =PRICE($K$7,$K$8,$I$7,($I$9+I14/10000),100,2,0) -> 77.248922 | K14: 4.95 | L14: =(J14-$I$8+K14)/$I$8 -> -0.14242126
A15: Senior Debentures | B15: 5.5 | C15: 2033 | D15: 428 | E15: Senior
A16: Senior Debentures | B16: 4.85 | C16: 2034 | D16: 87 | E16: Senior
A17: Senior Debentures | B17: 6.875 | C17: 2036 | D17: 1072 | E17: Senior
A18: Senior Debentures | B18: 6.75 | C18: 2037 | D18: 76 | E18: Senior
A19: Senior Notes | B19: 5.9 | C19: 2040 | D19: 298 | E19: Senior
A20: Senior Debentures | B20: 4.5 | C20: 2042 | D20: 45 | E20: Senior
A21: Senior Notes | B21: 4.85 | C21: 2042 | D21: 490 | E21: Senior
A22: Senior Debentures | B22: 4.375 | C22: 2043 | D22: 1146 | E22: Senior
A23: Senior Debentures | B23: 4.875 | C23: 2043 | D23: 18 | E23: Senior
A24: Senior Debentures | B24: 5.85 | C24: 2043 | D24: 1235 | E24: Senior
A25: Senior Debentures | B25: 5.25 | C25: 2044 | D25: 345 | E25: Senior
A26: Senior Notes | B26: 4.9 | C26: 2044 | D26: 542 | E26: Senior
... A30: Junior Subordinated Debentures | B30: 6.375 | C30: 2062 | D30: 989 | E30: Junior Subordinated
A32: Total Debt | D32: =SUM(D6:D30) -> 14501
A34: Due Before 2031 | D34: =SUM(D6:D12) -> 3333

Sheet Graphs & Tables
A1: Owen Purnomo
B4: Paramount | C4: 2022 | D4: 2023 | E4: 2024 | F4: 2025 | G4: 2026 | H4: 2027 | I4: 2028 | J4: 2029
B5: TV Media Revenue | C5: ='PSKY IS'!B5 -> 21732.156 | D5: ='PSKY IS'!C5 -> 20084.932 | E5: ='PSKY IS'!D5 -> 18778.745 | F5: ='PSKY IS'!E5 -> 18612.982 | G5: ='PSKY IS'!F5 -> 17651.094 | H5: ='PSKY IS'!G5 -> 16716.035 | I5: ='PSKY IS'!H5 -> 16040.303 | J5: ='PSKY IS'!I5 -> 15265.992
B6: Direct to Consumer Revenue | C6: ='PSKY IS'!B6 -> 4904 | D6: ='PSKY IS'!C6 -> 6736 | E6: ='PSKY IS'!D6 -> 7632 | F6: ='PSKY IS'!E6 -> 8494.6667 | G6: ='PSKY IS'!F6 -> 8664.56 | H6: ='PSKY IS'!G6 -> 8837.8512 | I6: ='PSKY IS'!H6 -> 9014.6082 | J6: ='PSKY IS'!I6 -> 9194.9004
B7: Filmed Entertainment Revenue | C7: ='PSKY IS'!B7 -> 3053 | D7: ='PSKY IS'!C7 -> 2957 | E7: ='PSKY IS'!D7 -> 2965 | F7: ='PSKY IS'!E7 -> 2900 | G7: ='PSKY IS'!F7 -> 3672.023 | H7: ='PSKY IS'!G7 -> 2635.0844 | I7: ='PSKY IS'!H7 -> 2420.9856 | J7: ='PSKY IS'!I7 -> 2381.8434
B8: Total Revenue | C8: =SUM(C5:C7) -> 29689.156 | D8: =SUM(D5:D7) -> 29777.932 | E8: =SUM(E5:E7) -> 29375.745 | F8: =SUM(F5:F7) -> 30007.649 | G8: =SUM(G5:G7) -> 29987.677 | H8: =SUM(H5:H7) -> 28188.971 | I8: =SUM(I5:I7) -> 27475.897 | J8: =SUM(J5:J7) -> 26842.735
B9: Adjusted EBITDA | C9: ='PSKY IS'!B28 -> 2747 | D9: ='PSKY IS'!C28 -> 50 | E9: ='PSKY IS'!D28 -> 2161 | F9: ='PSKY IS'!E28 -> 2097.7382 | G9: ='PSKY IS'!F28 -> 1420.4391 | H9: ='PSKY IS'!G28 -> 1193.0183 | I9: ='PSKY IS'!H28 -> 1048.4933 | J9: ='PSKY IS'!I28 -> 888.90637
B10: Adjusted EBIT | C10: ='PSKY IS'!B16 -> 2342 | D10: ='PSKY IS'!C16 -> -368 | E10: ='PSKY IS'!D16 -> 1769 | F10: ='PSKY IS'!E16 -> 1697.3059 | G10: ='PSKY IS'!F16 -> 1020.2733 | H10: ='PSKY IS'!G16 -> 816.85506 | I10: ='PSKY IS'!H16 -> 681.84556 | J10: ='PSKY IS'!I16 -> 530.70771
B11: Net Income | C11: ='PSKY IS'!B25 -> 1104 | D11: ='PSKY IS'!C25 -> -525 | E11: ='PSKY IS'!D25 -> 848 | F11: ='PSKY IS'!E25 -> 786.97254 | G11: ='PSKY IS'!F25 -> 109.93994 | H11: ='PSKY IS'!G25 -> -93.478272 | I11: ='PSKY IS'!H25 -> -228.48777 | J11: ='PSKY IS'!I25 -> -379.62562
B13: Percentage of Revenue | C13: 2022 | D13: 2023 | E13: 2024 | F13: 2025 | G13: 2026 | H13: 2027 | I13: 2028 | J13: 2029
B14: TV Media | C14: =C5/C8 -> 0.73198969 | D14: =D5/D8 -> 0.67449049 | E14: =E5/E8 -> 0.63926021 | F14: =F5/F8 -> 0.62027459 | G14: =G5/G8 -> 0.58861158 | H14: =H5/H8 -> 0.59299914 | I14: =I5/I8 -> 0.58379543 | J14: =J5/J8 -> 0.56871967
B15: Direct to Consumer | C15: =C6/C8 -> 0.16517815 | D15: =D6/D8 -> 0.22620779 | E15: =E6/E8 -> 0.25980618 | F15: =F6/F8 -> 0.28308338 | G15: =G6/G8 -> 0.28893735 | H15: =H6/H8 -> 0.3135216 | I15: =I6/I8 -> 0.3280915 | J15: =J6/J8 -> 0.34254707
B16: Filmed Entertainment | C16: =C7/C8 -> 0.10283216 | D16: =D7/D8 -> 0.099301725 | E16: =E7/E8 -> 0.10093361 | F16: =F7/F8 -> 0.096642026 | G16: =G7/G8 -> 0.12245107 | H16: =H7/H8 -> 0.093479268 | I16: =I7/I8 -> 0.088113069 | J16: =J7/J8 -> 0.088733261
B17: EBITDA Margin | C17: =C9/C8 -> 0.092525364 | D17: =D9/D8 -> 0.0016790958 | E17: =E9/E8 -> 0.073564093 | F17: =F9/F8 -> 0.069906783 | G17: =G9/G8 -> 0.047367427 | H17: =H9/H8 -> 0.042322167 | I17: =I9/I8 -> 0.038160477 | J17: =J9/J8 -> 0.033115342
B18: EBIT Margin | C18: =C10/C8 -> 0.07888402 | D18: =D10/D8 -> -0.012358145 | E18: =E10/E8 -> 0.06021975 | F18: =F10/F8 -> 0.056562441 | G18: =G10/G8 -> 0.034023084 | H18: =H10/H8 -> 0.028977825 | I18: =I10/I8 -> 0.024816135 | J18: =J10/J8 -> 0.019770999
B19: Net Income | C19: =C11/C8 -> 0.037185294 | D19: =D11/D8 -> -0.017630506 | E19: =E11/E8 -> 0.028867353 | F19: =F11/F8 -> 0.026225731 | G19: =G11/G8 -> 0.0036661704 | H19: =H11/H8 -> -0.0033161293 | I19: =I11/I8 -> -0.008315935 | J19: =J11/J8 -> -0.014142583
B21: Segement | C21: 2022 | D21: 2023 | E21: 2024 | F21: 2025 | G21: 2026 | H21: 2027 | I21: 2028 | J21: 2029
B22: =B14 -> TV Media | C22: =C14 -> 0.73198969 | D22: =D14 -> 0.67449049 | E22: =E14 -> 0.63926021 | F22: =F14 -> 0.62027459 | G22: =G14 -> 0.58861158 | H22: =H14 -> 0.59299914 | I22: =I14 -> 0.58379543 | J22: =J14 -> 0.56871967
B23: =B15 -> Direct to Consumer | C23: =C15 -> 0.16517815 | D23: =D15 -> 0.22620779 | E23: =E15 -> 0.25980618 | F23: =F15 -> 0.28308338 | G23: =G15 -> 0.28893735 | H23: =H15 -> 0.3135216 | I23: =I15 -> 0.3280915 | J23: =J15 -> 0.34254707
B24: =B16 -> Filmed Entertainment | C24: =C16 -> 0.10283216 | D24: =D16 -> 0.099301725 | E24: =E16 -> 0.10093361 | F24: =F16 -> 0.096642026 | G24: =G16 -> 0.12245107 | H24: =H16 -> 0.093479268 | I24: =I16 -> 0.088113069 | J24: =J16 -> 0.088733261
B26: Margins | C26: 2022 | D26: 2023 | E26: 2024 | F26: 2025 | G26: 2026 | H26: 2027 | I26: 2028 | J26: 2029
B27: {=B17:B19} -> EBITDA Margin | C27: =C17 -> 0.092525364 | D27: =D17 -> 0.0016790958 | E27: =E17 -> 0.073564093 | F27: =F17 -> 0.069906783 | G27: =G17 -> 0.047367427 | H27: =H17 -> 0.042322167 | I27: =I17 -> 0.038160477 | J27: =J17 -> 0.033115342
B28: EBIT Margin | C28: =C18 -> 0.07888402 | D28: =D18 -> -0.012358145 | E28: =E18 -> 0.06021975 | F28: =F18 -> 0.056562441 | G28: =G18 -> 0.034023084 | H28: =H18 -> 0.028977825 | I28: =I18 -> 0.024816135 | J28: =J18 -> 0.019770999
B29: Net Income | C29: =C19 -> 0.037185294 | D29: =D19 -> -0.017630506 | E29: =E19 -> 0.028867353 | F29: =F19 -> 0.026225731 | G29: =G19 -> 0.0036661704 | H29: =H19 -> -0.0033161293 | I29: =I19 -> -0.008315935 | J29: =J19 -> -0.014142583
B32: Credit Metrics | C32: 2024 | D32: 2025 | E32: 2026 | F32: 2027 | G32: 2028 | H32: 2029
B33: {='PSKY IS'!A38:A43} -> EBIT/Interest | C33: ='PSKY IS'!D38 -> 2.0569767 | D33: ='PSKY IS'!E38 -> 1.8782433 | E33: ='PSKY IS'!F38 -> 1.1290372 | F33: ='PSKY IS'!G38 -> 0.90393404 | G33: ='PSKY IS'!H38 -> 0.75453216 | H33: ='PSKY IS'!I38 -> 0.5872826
B34: EBITDA/Interest | C34: ='PSKY IS'!D39 -> 2.5127907 | D34: ='PSKY IS'!E39 -> 2.3213628 | E34: ='PSKY IS'!F39 -> 1.5718618 | F34: ='PSKY IS'!G39 -> 1.3201974 | G34: ='PSKY IS'!H39 -> 1.1602656 | H34: ='PSKY IS'!I39 -> 0.98366621
B35: (EBITDA - CAPEX)/Interest | C35: ='PSKY IS'!D40 -> 2.2069767 | D35: ='PSKY IS'!E40 -> 2.0557782 | E35: ='PSKY IS'!F40 -> 1.3062771 | F35: ='PSKY IS'!G40 -> 1.0546127 | G35: ='PSKY IS'!H40 -> 0.89468094 | H35: ='PSKY IS'!I40 -> 0.71808156
B36: Gross Debt/EBITDAR | C36: ='PSKY IS'!D41 -> 5.8209749 | D36: ='PSKY IS'!E41 -> 6.6564353 | E36: ='PSKY IS'!F41 -> 9.3429965 | F36: ='PSKY IS'!G41 -> 10.769073 | G36: ='PSKY IS'!H41 -> 11.380576 | H36: ='PSKY IS'!I41 -> 13.12611
B37: NET Debt/EBITDAR | C37: ='PSKY IS'!D42 -> 6.8136219 | D37: ='PSKY IS'!E42 -> 7.767209 | E37: ='PSKY IS'!F42 -> 10.944953 | F37: ='PSKY IS'!G42 -> 12.686661 | G37: ='PSKY IS'!H42 -> 13.550134 | H37: ='PSKY IS'!I42 -> 15.720003
B38: FCF/ Debt | C38: ='PSKY IS'!D43 -> 0.011839994 | D38: ='PSKY IS'!E43 -> 0.0062268304 | E38: ='PSKY IS'!F43 -> -0.029129323 | F38: ='PSKY IS'!G43 -> -0.041122766 | G38: ='PSKY IS'!H43 -> -0.049066036 | H38: ='PSKY IS'!I43 -> -0.058738436
